Workbook

Sheet 订货1
A1: 每月更新日期 | B1: 45962 | C1: 每月请将食材マスター的下记内容复制粘贴在A-J列 | K1: 月初填写 | L1: 订货日期↓ | M1: 点击下框，选店号↓ | N1: 订货人姓名↓ | O1: 注意事项：①《浅蓝》为必填内容。 | T1: 注意填写正确信息
A2: =TODAY() -> 45978 | B2: =B1+1 -> 45963 | H2: =L2+1 -> 45979 | J2: 开店时完成更新 | K2: =B1 -> 45962 | L2: =A2 -> 45978 | M2: 059嘉亭荟 | N2: 袁艳艳 | T2: 浅绿色每次订货需要确认修改↓ | AB2: 订货数
A3: 商品编码 | B3: 商品名 | C3: 保存条件 | D3: 保质期 | E3: 包装規格 | F3: 注文単位 | G3: 供应商名 | H3: 生产商 | I3: 配送 | J3: 店序列 | L3: 供应商名 | M3: 商品名 | N3: 下次送货日↓ | O3: 保管 | P3: 规格 | Q3: 订货单位 | R3: 建议量 | S3: 订货限定 | T3: SALES预估 | U3: 万元用量 | V3: 安全系数 | W3: 需求量 | X3: 库存量 | Y3: 前次合计 | Z3: 前次（1） | AA3: 前次（2） | AB3: =B1 -> 45962 | AC3: =AB3+1 -> 45963 | AD3: =AC3+1 -> 45964 | AE3: =AD3+1 -> 45965 | AF3: =AE3+1 -> 45966 | AG3: =AF3+1 -> 45967 | AH3: =AG3+1 -> 45968 | AI3: =AH3+1 -> 45969 | AJ3: =AI3+1 -> 45970 | ... BF3: =BE3+1 -> 45992 | BG3: 配送 | BH3: 生产商名称
A4: 101729 | B4: 可可粉 | C4: 常温 | E4: 0.5kg | F4: 包 | G4: 熠沣实业（上海）有限公司 | H4: 启东欧瑞食品有限公司 | I4: 由仓库 | K4: =VLOOKUP($A4,订货1!$A4:$A243,1,0) -> 101729 | L4: =VLOOKUP($A4,订货1!$A4:$G243,7,0) -> 熠沣实业（上海）有限公司 | M4: =VLOOKUP($A4,订货1!$A4:$B243,2,0) -> 可可粉 | N4: 45978 | O4: =VLOOKUP($A4,订货1!$A4:$C243,3,0) -> 常温 | P4: =VLOOKUP($A4,订货1!$A4:$E243,5,0) -> 0.5kg | Q4: =VLOOKUP($A4,订货1!$A4:$F243,6,0) -> 包 | R4: =IF(ROUNDUP(W4-Y4-X4,0)>=0,ROUNDUP((W4-Y4-X4),0),0) -> 0 | S4: 全店 | T4: =SUMIF(预估营业额3!$B$3:$B$39,">="&$H$2,预估营业额3!$E$3:$E$39)-SUMIF(预估营业额3!$B$3:$B$39,">"&N4,预估营业额3!$E$3:$E$39) -> 0 | U4: 0.0041935168 | V4: 1 | W4: =T4*U4*V4 -> 0 | X4: 1 | Y4: =Z4+AA4 -> 0 | BG4: =VLOOKUP($A4,订货1!$A4:$I243,9,0) -> 由仓库 | BH4: =VLOOKUP($A4,订货1!$A4:$H243,8,0) -> 启东欧瑞食品有限公司
A5: 101727 | B5: 冷冻意大利面 | C5: 冷凍 | E5: 200g*30 | F5: 箱 | G5: 青岛亚是加食品有限公司 | H5: 青岛亚是加食品有限公司 | I5: 由仓库 | K5: =VLOOKUP($A5,订货1!$A5:$A244,1,0) -> 101727 | L5: =VLOOKUP($A5,订货1!$A5:$G244,7,0) -> 青岛亚是加食品有限公司 | M5: =VLOOKUP($A5,订货1!$A5:$B244,2,0) -> 冷冻意大利面 | N5: =$N$4 -> 45978 | O5: =VLOOKUP($A5,订货1!$A5:$C244,3,0) -> 冷凍 | P5: =VLOOKUP($A5,订货1!$A5:$E244,5,0) -> 200g*30 | Q5: =VLOOKUP($A5,订货1!$A5:$F244,6,0) -> 箱 | R5: =IF(ROUNDUP(W5-Y5-X5,0)>=0,ROUNDUP((W5-Y5-X5),0),0) -> 0 | S5: 实验店 | T5: =SUMIF(预估营业额3!$B$3:$B$39,">="&$H$2,预估营业额3!$E$3:$E$39)-SUMIF(预估营业额3!$B$3:$B$39,">"&N5,预估营业额3!$E$3:$E$39) -> 0 | U5: 0 | V5: 1 | W5: =T5*U5*V5 -> 0 | X5: 0 | Y5: =Z5+AA5 -> 0 | BG5: =VLOOKUP($A5,订货1!$A5:$I244,9,0) -> 由仓库 | BH5: =VLOOKUP($A5,订货1!$A5:$H244,8,0) -> 青岛亚是加食品有限公司
A6: 101730 | B6: 利梭多粉 | C6: 常温 | E6: 33g*20包*20袋/箱 | F6: 箱 | G6: 卓典食品科技（江苏）有限公司 | H6: 卓典食品科技（江苏）有限公司 | I6: 由仓库 | K6: =VLOOKUP($A6,订货1!$A6:$A245,1,0) -> 101730 | L6: =VLOOKUP($A6,订货1!$A6:$G245,7,0) -> 卓典食品科技（江苏）有限公司 | M6: =VLOOKUP($A6,订货1!$A6:$B245,2,0) -> 利梭多粉 | N6: =$N$4 -> 45978 | O6: =VLOOKUP($A6,订货1!$A6:$C245,3,0) -> 常温 | P6: =VLOOKUP($A6,订货1!$A6:$E245,5,0) -> 33g*20包*20袋/箱 | Q6: =VLOOKUP($A6,订货1!$A6:$F245,6,0) -> 箱 | R6: =IF(ROUNDUP(W6-Y6-X6,0)>=0,ROUNDUP((W6-Y6-X6),0),0) -> 0 | S6: 全店 | T6: =SUMIF(预估营业额3!$B$3:$B$39,">="&$H$2,预估营业额3!$E$3:$E$39)-SUMIF(预估营业额3!$B$3:$B$39,">"&N6,预估营业额3!$E$3:$E$39) -> 0 | U6: 0.0045429766 | V6: 1 | W6: =T6*U6*V6 -> 0 | X6: 0.25 | Y6: =Z6+AA6 -> 0 | BG6: =VLOOKUP($A6,订货1!$A6:$I245,9,0) -> 由仓库 | BH6: =VLOOKUP($A6,订货1!$A6:$H245,8,0) -> 卓典食品科技（江苏）有限公司
A7: 101739 | B7: 华美裹粉鸡胗 | C7: 冷凍 | E7: 40g*20*12 | F7: 箱 | G7: 沈阳华美食品有限公司 | H7: 沈阳华美食品有限公司 | I7: 由仓库 | K7: =VLOOKUP($A7,订货1!$A7:$A246,1,0) -> 101739 | L7: =VLOOKUP($A7,订货1!$A7:$G246,7,0) -> 沈阳华美食品有限公司 | M7: =VLOOKUP($A7,订货1!$A7:$B246,2,0) -> 华美裹粉鸡胗 | N7: =$N$4 -> 45978 | O7: =VLOOKUP($A7,订货1!$A7:$C246,3,0) -> 冷凍 | P7: =VLOOKUP($A7,订货1!$A7:$E246,5,0) -> 40g*20*12 | Q7: =VLOOKUP($A7,订货1!$A7:$F246,6,0) -> 箱 | R7: =IF(ROUNDUP(W7-Y7-X7,0)>=0,ROUNDUP((W7-Y7-X7),0),0) -> 0 | S7: 全店 | T7: =SUMIF(预估营业额3!$B$3:$B$39,">="&$H$2,预估营业额3!$E$3:$E$39)-SUMIF(预估营业额3!$B$3:$B$39,">"&N7,预估营业额3!$E$3:$E$39) -> 0 | U7: 0.025743534 | V7: 1 | W7: =T7*U7*V7 -> 0 | X7: 0 | Y7: =Z7+AA7 -> 0 | BG7: =VLOOKUP($A7,订货1!$A7:$I246,9,0) -> 由仓库 | BH7: =VLOOKUP($A7,订货1!$A7:$H246,8,0) -> 沈阳华美食品有限公司
A8: 101752 | B8: 冷冻土豆泥 | C8: 冷凍 | E8: 1kg*10 | F8: 箱 | G8: 山東三涛食品有限公司 | H8: 山東三涛食品有限公司 | I8: 由仓库 | J8: 045巴黎春天宝山店（松江） | K8: =VLOOKUP($A8,订货1!$A8:$A248,1,0) -> 101752 | L8: =VLOOKUP($A8,订货1!$A8:$G248,7,0) -> 山東三涛食品有限公司 | M8: =VLOOKUP($A8,订货1!$A8:$B248,2,0) -> 冷冻土豆泥 | N8: =$N$4 -> 45978 | O8: =VLOOKUP($A8,订货1!$A8:$C248,3,0) -> 冷凍 | P8: =VLOOKUP($A8,订货1!$A8:$E248,5,0) -> 1kg*10 | Q8: =VLOOKUP($A8,订货1!$A8:$F248,6,0) -> 箱 | R8: =IF(ROUNDUP(W8-Y8-X8,0)>=0,ROUNDUP((W8-Y8-X8),0),0) -> 0 | S8: 实验店 | T8: =SUMIF(预估营业额3!$B$3:$B$39,">="&$H$2,预估营业额3!$E$3:$E$39)-SUMIF(预估营业额3!$B$3:$B$39,">"&N8,预估营业额3!$E$3:$E$39) -> 0 | U8: 0 | V8: 1 | W8: =T8*U8*V8 -> 0 | X8: 0 | Y8: =Z8+AA8 -> 0 | BG8: =VLOOKUP($A8,订货1!$A8:$I248,9,0) -> 由仓库 | BH8: =VLOOKUP($A8,订货1!$A8:$H248,8,0) -> 山東三涛食品有限公司
A9: 101686 | B9: 黄桃丁罐头（825g） | C9: 常温 | E9: 0.825kg*24can | F9: 箱 | G9: 融滋合味（上海）科技有限公司 | H9: 宿州皇冠食品有限公司 | I9: 由仓库 | J9: 050南京环亚店 | K9: =VLOOKUP($A9,订货1!$A9:$A250,1,0) -> 101686 | L9: =VLOOKUP($A9,订货1!$A9:$G250,7,0) -> 融滋合味（上海）科技有限公司 | M9: =VLOOKUP($A9,订货1!$A9:$B250,2,0) -> 黄桃丁罐头（825g） | N9: =$N$4 -> 45978 | O9: =VLOOKUP($A9,订货1!$A9:$C250,3,0) -> 常温 | P9: =VLOOKUP($A9,订货1!$A9:$E250,5,0) -> 0.825kg*24can | Q9: =VLOOKUP($A9,订货1!$A9:$F250,6,0) -> 箱 | R9: =IF(ROUNDUP(W9-Y9-X9,0)>=0,ROUNDUP((W9-Y9-X9),0),0) -> 0 | S9: 全店 | T9: =SUMIF(预估营业额3!$B$3:$B$39,">="&$H$2,预估营业额3!$E$3:$E$39)-SUMIF(预估营业额3!$B$3:$B$39,">"&N9,预估营业额3!$E$3:$E$39) -> 0 | U9: 0.039023004 | V9: 1 | W9: =T9*U9*V9 -> 0 | X9: 0.5 | Y9: =Z9+AA9 -> 0 | AI9: 1 | BG9: =VLOOKUP($A9,订货1!$A9:$I250,9,0) -> 由仓库 | BH9: =VLOOKUP($A9,订货1!$A9:$H250,8,0) -> 宿州皇冠食品有限公司
A10: 101112 | B10: 亨氏番茄调味酱 | C10: 常温 | E10: 10g*600pc | F10: 箱 | G10: 上海捷仪经贸有限公司 | H10: 亨氏（青岛）食品有限公司 | I10: 由仓库 | J10: 058莘庄龙之梦店（松江） | K10: =VLOOKUP($A10,订货1!$A10:$A251,1,0) -> 101112 | L10: =VLOOKUP($A10,订货1!$A10:$G251,7,0) -> 上海捷仪经贸有限公司 | M10: =VLOOKUP($A10,订货1!$A10:$B251,2,0) -> 亨氏番茄调味酱 | N10: =$N$4 -> 45978 | O10: =VLOOKUP($A10,订货1!$A10:$C251,3,0) -> 常温 | P10: =VLOOKUP($A10,订货1!$A10:$E251,5,0) -> 10g*600pc | Q10: =VLOOKUP($A10,订货1!$A10:$F251,6,0) -> 箱 | R10: =IF(ROUNDUP(W10-Y10-X10,0)>=0,ROUNDUP((W10-Y10-X10),0),0) -> 0 | S10: 全店 | T10: =SUMIF(预估营业额3!$B$3:$B$39,">="&$H$2,预估营业额3!$E$3:$E$39)-SUMIF(预估营业额3!$B$3:$B$39,">"&N10,预估营业额3!$E$3:$E$39) -> 0 | U10: 0.031008727 | V10: 1 | W10: =T10*U10*V10 -> 0 | X10: 0.3 | Y10: =Z10+AA10 -> 0 | AC10: 1 | AM10: 1 | BG10: =VLOOKUP($A10,订货1!$A10:$I251,9,0) -> 由仓库 | BH10: =VLOOKUP($A10,订货1!$A10:$H251,8,0) -> 亨氏（青岛）食品有限公司
A11: 101687 | B11: 椰果罐头（850g） | C11: 常温 | E11: 0.85kg*12can | F11: 箱 | G11: 上海潜深实业有限公司 | H11: 雷州市绿河食品实业有限公司 | I11: 由仓库 | J11: 059嘉亭荟 | K11: =VLOOKUP($A11,订货1!$A11:$A252,1,0) -> 101687 | L11: =VLOOKUP($A11,订货1!$A11:$G252,7,0) -> 上海潜深实业有限公司 | M11: =VLOOKUP($A11,订货1!$A11:$B252,2,0) -> 椰果罐头（850g） | N11: =$N$4 -> 45978 | O11: =VLOOKUP($A11,订货1!$A11:$C252,3,0) -> 常温 | P11: =VLOOKUP($A11,订货1!$A11:$E252,5,0) -> 0.85kg*12can | Q11: =VLOOKUP($A11,订货1!$A11:$F252,6,0) -> 箱 | R11: =IF(ROUNDUP(W11-Y11-X11,0)>=0,ROUNDUP((W11-Y11-X11),0),0) -> 0 | S11: 全店 | T11: =SUMIF(预估营业额3!$B$3:$B$39,">="&$H$2,预估营业额3!$E$3:$E$39)-SUMIF(预估营业额3!$B$3:$B$39,">"&N11,预估营业额3!$E$3:$E$39) -> 0 | U11: 0.064067618 | V11: 1 | W11: =T11*U11*V11 -> 0 | X11: 1 | Y11: =Z11+AA11 -> 0 | AG11: 1 | AM11: 1 | BG11: =VLOOKUP($A11,订货1!$A11:$I252,9,0) -> 由仓库 | BH11: =VLOOKUP($A11,订货1!$A11:$H252,8,0) -> 雷州市绿河食品实业有限公司
A12: 101738 | B12: （组）巴氏杀菌冰全蛋 | C12: 冷凍 | E12: 970g*6 | F12: 组 | G12: 苏州欧福蛋液股份有限公司 | H12: 苏州欧福蛋液股份有限公司 | I12: 由仓库 | J12: 065真光路二店 | K12: =VLOOKUP($A12,订货1!$A12:$A253,1,0) -> 101738 | L12: =VLOOKUP($A12,订货1!$A12:$G253,7,0) -> 苏州欧福蛋液股份有限公司 | M12: =VLOOKUP($A12,订货1!$A12:$B253,2,0) -> （组）巴氏杀菌冰全蛋 | N12: =$N$4 -> 45978 | O12: =VLOOKUP($A12,订货1!$A12:$C253,3,0) -> 冷凍 | P12: =VLOOKUP($A12,订货1!$A12:$E253,5,0) -> 970g*6 | Q12: =VLOOKUP($A12,订货1!$A12:$F253,6,0) -> 组 | R12: =IF(ROUNDUP(W12-Y12-X12,0)>=0,ROUNDUP((W12-Y12-X12),0),0) -> 0 | S12: 全店 | T12: =SUMIF(预估营业额3!$B$3:$B$39,">="&$H$2,预估营业额3!$E$3:$E$39)-SUMIF(预估营业额3!$B$3:$B$39,">"&N12,预估营业额3!$E$3:$E$39) -> 0 | U12: 0.090381576 | V12: 1 | W12: =T12*U12*V12 -> 0 | X12: 0.6 | Y12: =Z12+AA12 -> 1 | Z12: 1 | AG12: 1 | AN12: 1 | BG12: =VLOOKUP($A12,订货1!$A12:$I253,9,0) -> 由仓库 | BH12: =VLOOKUP($A12,订货1!$A12:$H253,8,0) -> 苏州欧福蛋液股份有限公司
A13: 101688 | B13: 奶油蘑菇汤 | C13: 冷凍 | E13: 0.16kg*50pc | F13: 箱 | G13: 上海宝立食品科技股份有限公司 | H13: 浙江宝立食品科技有限公司 | I13: 由仓库 | J13: 067南京德盈店 | K13: =VLOOKUP($A13,订货1!$A13:$A254,1,0) -> 101688 | L13: =VLOOKUP($A13,订货1!$A13:$G254,7,0) -> 上海宝立食品科技股份有限公司 | M13: =VLOOKUP($A13,订货1!$A13:$B254,2,0) -> 奶油蘑菇汤 | N13: =$N$4 -> 45978 | O13: =VLOOKUP($A13,订货1!$A13:$C254,3,0) -> 冷凍 | P13: =VLOOKUP($A13,订货1!$A13:$E254,5,0) -> 0.16kg*50pc | Q13: =VLOOKUP($A13,订货1!$A13:$F254,6,0) -> 箱 | R13: =IF(ROUNDUP(W13-Y13-X13,0)>=0,ROUNDUP((W13-Y13-X13),0),0) -> 0 | S13: 全店 | T13: =SUMIF(预估营业额3!$B$3:$B$39,">="&$H$2,预估营业额3!$E$3:$E$39)-SUMIF(预估营业额3!$B$3:$B$39,">"&N13,预估营业额3!$E$3:$E$39) -> 0 | U13: 0.4 | V13: 1 | W13: =T13*U13*V13 -> 0 | X13: 1.3 | Y13: =Z13+AA13 -> 2 | Z13: 2 | AB13: 1 | AE13: 2 | AF13: 1 | AG13: 2 | AI13: 1 | AM13: 2 | AN13: 2 | AO13: 1 | BG13: =VLOOKUP($A13,订货1!$A13:$I254,9,0) -> 由仓库 | BH13: =VLOOKUP($A13,订货1!$A13:$H254,8,0) -> 浙江宝立食品科技有限公司
A14: 101290 | B14: 黑胡椒碎 | C14: 常温 | E14: 1kg | F14: 袋 | G14: 上海捷仪经贸有限公司 | H14: 泰州顶淳食品有限公司 | I14: 由仓库 | J14: 069宣化路店 | K14: =VLOOKUP($A14,订货1!$A14:$A255,1,0) -> 101290 | L14: =VLOOKUP($A14,订货1!$A14:$G255,7,0) -> 上海捷仪经贸有限公司 | M14: =VLOOKUP($A14,订货1!$A14:$B255,2,0) -> 黑胡椒碎 | N14: =$N$4 -> 45978 | O14: =VLOOKUP($A14,订货1!$A14:$C255,3,0) -> 常温 | P14: =VLOOKUP($A14,订货1!$A14:$E255,5,0) -> 1kg | Q14: =VLOOKUP($A14,订货1!$A14:$F255,6,0) -> 袋 | R14: =IF(ROUNDUP(W14-Y14-X14,0)>=0,ROUNDUP((W14-Y14-X14),0),0) -> 0 | S14: 全店 | T14: =SUMIF(预估营业额3!$B$3:$B$39,">="&$H$2,预估营业额3!$E$3:$E$39)-SUMIF(预估营业额3!$B$3:$B$39,">"&N14,预估营业额3!$E$3:$E$39) -> 0 | U14: 0.0069891947 | V14: 1 | W14: =T14*U14*V14 -> 0 | X14: 1 | Y14: =Z14+AA14 -> 0 | BG14: =VLOOKUP($A14,订货1!$A14:$I255,9,0) -> 由仓库 | BH14: =VLOOKUP($A14,订货1!$A14:$H255,8,0) -> 泰州顶淳食品有限公司
A15: 101398 | B15: 好日子红茶 | C15: 常温 | E15: 2g*100pc*30pc大 | F15: 袋 | G15: 上海捷仪经贸有限公司 | H15: 福建好日子食品有限公司 | I15: 由仓库 | J15: 071长阳路店 | K15: =VLOOKUP($A15,订货1!$A15:$A256,1,0) -> 101398 | L15: =VLOOKUP($A15,订货1!$A15:$G256,7,0) -> 上海捷仪经贸有限公司 | M15: =VLOOKUP($A15,订货1!$A15:$B256,2,0) -> 好日子红茶 | N15: =$N$4 -> 45978 | O15: =VLOOKUP($A15,订货1!$A15:$C256,3,0) -> 常温 | P15: =VLOOKUP($A15,订货1!$A15:$E256,5,0) -> 2g*100pc*30pc大 | Q15: =VLOOKUP($A15,订货1!$A15:$F256,6,0) -> 袋 | R15: =IF(ROUNDUP(W15-Y15-X15,0)>=0,ROUNDUP((W15-Y15-X15),0),0) -> 0 | S15: 全店 | T15: =SUMIF(预估营业额3!$B$3:$B$39,">="&$H$2,预估营业额3!$E$3:$E$39)-SUMIF(预估营业额3!$B$3:$B$39,">"&N15,预估营业额3!$E$3:$E$39) -> 0 | U15: 0.013139686 | V15: 1 | W15: =T15*U15*V15 -> 0 | X15: 1 | Y15: =Z15+AA15 -> 0 | BG15: =VLOOKUP($A15,订货1!$A15:$I256,9,0) -> 由仓库 | BH15: =VLOOKUP($A15,订货1!$A15:$H256,8,0) -> 福建好日子食品有限公司
A16: 101399 | B16: 好日子绿茶 | C16: 常温 | E16: 2g*100pc*30pc大 | F16: 袋 | G16: 上海捷仪经贸有限公司 | H16: 福建好日子食品有限公司 | I16: 由仓库 | J16: 073金山百联店（松江） | K16: =VLOOKUP($A16,订货1!$A16:$A257,1,0) -> 101399 | L16: =VLOOKUP($A16,订货1!$A16:$G257,7,0) -> 上海捷仪经贸有限公司 | M16: =VLOOKUP($A16,订货1!$A16:$B257,2,0) -> 好日子绿茶 | N16: =$N$4 -> 45978 | O16: =VLOOKUP($A16,订货1!$A16:$C257,3,0) -> 常温 | P16: =VLOOKUP($A16,订货1!$A16:$E257,5,0) -> 2g*100pc*30pc大 | Q16: =VLOOKUP($A16,订货1!$A16:$F257,6,0) -> 袋 | R16: =IF(ROUNDUP(W16-Y16-X16,0)>=0,ROUNDUP((W16-Y16-X16),0),0) -> 0 | S16: 全店 | T16: =SUMIF(预估营业额3!$B$3:$B$39,">="&$H$2,预估营业额3!$E$3:$E$39)-SUMIF(预估营业额3!$B$3:$B$39,">"&N16,预估营业额3!$E$3:$E$39) -> 0 | U16: 0.0037741651 | V16: 1 | W16: =T16*U16*V16 -> 0 | X16: 0.1 | Y16: =Z16+AA16 -> 0 | BG16: =VLOOKUP($A16,订货1!$A16:$I257,9,0) -> 由仓库 | BH16: =VLOOKUP($A16,订货1!$A16:$H257,8,0) -> 福建好日子食品有限公司
A17: 101400 | B17: 好日子茉莉花茶 | C17: 常温 | E17: 2g*100pc*30pc大 | F17: 袋 | G17: 上海捷仪经贸有限公司 | H17: 福建好日子食品有限公司 | I17: 由仓库 | J17: 074香港名都（松江） | K17: =VLOOKUP($A17,订货1!$A17:$A258,1,0) -> 101400 | L17: =VLOOKUP($A17,订货1!$A17:$G258,7,0) -> 上海捷仪经贸有限公司 | M17: =VLOOKUP($A17,订货1!$A17:$B258,2,0) -> 好日子茉莉花茶 | N17: =$N$4 -> 45978 | O17: =VLOOKUP($A17,订货1!$A17:$C258,3,0) -> 常温 | P17: =VLOOKUP($A17,订货1!$A17:$E258,5,0) -> 2g*100pc*30pc大 | Q17: =VLOOKUP($A17,订货1!$A17:$F258,6,0) -> 袋 | R17: =IF(ROUNDUP(W17-Y17-X17,0)>=0,ROUNDUP((W17-Y17-X17),0),0) -> 0 | S17: 全店 | T17: =SUMIF(预估营业额3!$B$3:$B$39,">="&$H$2,预估营业额3!$E$3:$E$39)-SUMIF(预估营业额3!$B$3:$B$39,">"&N17,预估营业额3!$E$3:$E$39) -> 0 | U17: 0.017752555 | V17: 1 | W17: =T17*U17*V17 -> 0 | X17: 1 | Y17: =Z17+AA17 -> 0 | AM17: 1 | BG17: =VLOOKUP($A17,订货1!$A17:$I258,9,0) -> 由仓库 | BH17: =VLOOKUP($A17,订货1!$A17:$H258,8,0) -> 福建好日子食品有限公司
A18: 201276 | B18: 白糖包 | C18: 常温 | E18: 7g*250pc | F18: 袋 | G18: 上海捷仪经贸有限公司 | H18: 广州华糖食品有限公司 | I18: 由仓库 | J18: 080沪航公路店（松江） | K18: =VLOOKUP($A18,订货1!$A18:$A259,1,0) -> 201276 | L18: =VLOOKUP($A18,订货1!$A18:$G259,7,0) -> 上海捷仪经贸有限公司 | M18: =VLOOKUP($A18,订货1!$A18:$B259,2,0) -> 白糖包 | N18: =$N$4 -> 45978 | O18: =VLOOKUP($A18,订货1!$A18:$C259,3,0) -> 常温 | P18: =VLOOKUP($A18,订货1!$A18:$E259,5,0) -> 7g*250pc | Q18: =VLOOKUP($A18,订货1!$A18:$F259,6,0) -> 袋 | R18: =IF(ROUNDUP(W18-Y18-X18,0)>=0,ROUNDUP((W18-Y18-X18),0),0) -> 0 | S18: 全店 | T18: =SUMIF(预估营业额3!$B$3:$B$39,">="&$H$2,预估营业额3!$E$3:$E$39)-SUMIF(预估营业额3!$B$3:$B$39,">"&N18,预估营业额3!$E$3:$E$39) -> 0 | U18: 0.0050322202 | V18: 1 | W18: =T18*U18*V18 -> 0 | X18: 1 | Y18: =Z18+AA18 -> 0 | AM18: 1 | BG18: =VLOOKUP($A18,订货1!$A18:$I259,9,0) -> 由仓库 | BH18: =VLOOKUP($A18,订货1!$A18:$H259,8,0) -> 广州华糖食品有限公司
A19: 101650 | B19: 干辣椒段 | C19: 常温 | E19: 1kg | F19: 箱 | G19: 川商（大連）貿易有限公司 | H19: 河北乾亿食品股份有限公司 | I19: 由仓库 | J19: 082七宝凯德嘉茂 | K19: =VLOOKUP($A19,订货1!$A19:$A260,1,0) -> 101650 | L19: =VLOOKUP($A19,订货1!$A19:$G260,7,0) -> 川商（大連）貿易有限公司 | M19: =VLOOKUP($A19,订货1!$A19:$B260,2,0) -> 干辣椒段 | N19: =$N$4 -> 45978 | O19: =VLOOKUP($A19,订货1!$A19:$C260,3,0) -> 常温 | P19: =VLOOKUP($A19,订货1!$A19:$E260,5,0) -> 1kg | Q19: =VLOOKUP($A19,订货1!$A19:$F260,6,0) -> 箱 | R19: =IF(ROUNDUP(W19-Y19-X19,0)>=0,ROUNDUP((W19-Y19-X19),0),0) -> 0 | S19: 全店 | T19: =SUMIF(预估营业额3!$B$3:$B$39,">="&$H$2,预估营业额3!$E$3:$E$39)-SUMIF(预估营业额3!$B$3:$B$39,">"&N19,预估营业额3!$E$3:$E$39) -> 0 | U19: 0.036343812 | V19: 1 | W19: =T19*U19*V19 -> 0 | X19: 1 | Y19: =Z19+AA19 -> 0 | AM19: 1 | BG19: =VLOOKUP($A19,订货1!$A19:$I260,9,0) -> 由仓库 | BH19: =VLOOKUP($A19,订货1!$A19:$H260,8,0) -> 河北乾亿食品股份有限公司
A20: 101025 | B20: 大蒜黄油 | C20: 冷凍 | E20: 3kg*4pc | F20: 箱 | G20: 嘉兴铃吉食品有限公司 | H20: 嘉兴铃吉食品有限公司 | I20: 由仓库 | J20: 083三号湾 | K20: =VLOOKUP($A20,订货1!$A20:$A261,1,0) -> 101025 | L20: =VLOOKUP($A20,订货1!$A20:$G261,7,0) -> 嘉兴铃吉食品有限公司 | M20: =VLOOKUP($A20,订货1!$A20:$B261,2,0) -> 大蒜黄油 | N20: =$N$4 -> 45978 | O20: =VLOOKUP($A20,订货1!$A20:$C261,3,0) -> 冷凍 | P20: =VLOOKUP($A20,订货1!$A20:$E261,5,0) -> 3kg*4pc | Q20: =VLOOKUP($A20,订货1!$A20:$F261,6,0) -> 箱 | R20: =IF(ROUNDUP(W20-Y20-X20,0)>=0,ROUNDUP((W20-Y20-X20),0),0) -> 0 | S20: 江浙店铺（宁波余姚除外） | T20: =SUMIF(预估营业额3!$B$3:$B$39,">="&$H$2,预估营业额3!$E$3:$E$39)-SUMIF(预估营业额3!$B$3:$B$39,">"&N20,预估营业额3!$E$3:$E$39) -> 0 | U20: 0 | V20: 1 | W20: =T20*U20*V20 -> 0 | X20: 2.25 | Y20: =Z20+AA20 -> 0 | BG20: =VLOOKUP($A20,订货1!$A20:$I261,9,0) -> 由仓库 | BH20: =VLOOKUP($A20,订货1!$A20:$H261,8,0) -> 嘉兴铃吉食品有限公司
A21: 101027 | B21: 酱蒜汁 | C21: 冷凍 | E21: 1kg*6pc | F21: 箱 | G21: 嘉兴铃吉食品有限公司 | H21: 嘉兴铃吉食品有限公司 | I21: 由仓库 | J21: 088正大乐城店 | K21: =VLOOKUP($A21,订货1!$A21:$A262,1,0) -> 101027 | L21: =VLOOKUP($A21,订货1!$A21:$G262,7,0) -> 嘉兴铃吉食品有限公司 | M21: =VLOOKUP($A21,订货1!$A21:$B262,2,0) -> 酱蒜汁 | N21: =$N$4 -> 45978 | O21: =VLOOKUP($A21,订货1!$A21:$C262,3,0) -> 冷凍 | P21: =VLOOKUP($A21,订货1!$A21:$E262,5,0) -> 1kg*6pc | Q21: =VLOOKUP($A21,订货1!$A21:$F262,6,0) -> 箱 | R21: =IF(ROUNDUP(W21-Y21-X21,0)>=0,ROUNDUP((W21-Y21-X21),0),0) -> 0 | S21: 全店 | T21: =SUMIF(预估营业额3!$B$3:$B$39,">="&$H$2,预估营业额3!$E$3:$E$39)-SUMIF(预估营业额3!$B$3:$B$39,">"&N21,预估营业额3!$E$3:$E$39) -> 0 | U21: 0.033781108 | V21: 1 | W21: =T21*U21*V21 -> 0 | X21: 0.83333333 | Y21: =Z21+AA21 -> 0 | AH21: 1 | BG21: =VLOOKUP($A21,订货1!$A21:$I262,9,0) -> 由仓库 | BH21: =VLOOKUP($A21,订货1!$A21:$H262,8,0) -> 嘉兴铃吉食品有限公司
A22: 101732 | B22: 榴莲果肉 | C22: 冷凍 | E22: 1kg | F22: 包 | G22: 融滋合味（上海）科技有限公司 | H22: Sunshine International Co., Ltd | I22: 由仓库 | J22: 089中星城店 | K22: =VLOOKUP($A22,订货1!$A22:$A263,1,0) -> 101732 | L22: =VLOOKUP($A22,订货1!$A22:$G263,7,0) -> 融滋合味（上海）科技有限公司 | M22: =VLOOKUP($A22,订货1!$A22:$B263,2,0) -> 榴莲果肉 | N22: =$N$4 -> 45978 | O22: =VLOOKUP($A22,订货1!$A22:$C263,3,0) -> 冷凍 | P22: =VLOOKUP($A22,订货1!$A22:$E263,5,0) -> 1kg | Q22: =VLOOKUP($A22,订货1!$A22:$F263,6,0) -> 包 | R22: =IF(ROUNDUP(W22-Y22-X22,0)>=0,ROUNDUP((W22-Y22-X22),0),0) -> 0 | S22: 全店 | T22: =SUMIF(预估营业额3!$B$3:$B$39,">="&$H$2,预估营业额3!$E$3:$E$39)-SUMIF(预估营业额3!$B$3:$B$39,">"&N22,预估营业额3!$E$3:$E$39) -> 0 | U22: 0.7 | V22: 1 | W22: =T22*U22*V22 -> 0 | X22: 3 | Y22: =Z22+AA22 -> 2 | Z22: 2 | AB22: 1 | AC22: 2 | AE22: 1 | AF22: 2 | AG22: 2 | AJ22: 2 | AM22: 3 | AN22: 2 | AO22: 1 | BG22: =VLOOKUP($A22,订货1!$A22:$I263,9,0) -> 由仓库 | BH22: =VLOOKUP($A22,订货1!$A22:$H263,8,0) -> Sunshine International Co., Ltd
A23: 101617 | B23: 冻鱿鱼 | C23: 冷凍 | E23: 1kg*10pkt | F23: 箱 | G23: 丹东永明食品有限公司 | H23: 丹东永明食品有限公司 | I23: 由仓库 | J23: 090苏州万科美好广场 | K23: =VLOOKUP($A23,订货1!$A23:$A264,1,0) -> 101617 | L23: =VLOOKUP($A23,订货1!$A23:$G264,7,0) -> 丹东永明食品有限公司 | M23: =VLOOKUP($A23,订货1!$A23:$B264,2,0) -> 冻鱿鱼 | N23: =$N$4 -> 45978 | O23: =VLOOKUP($A23,订货1!$A23:$C264,3,0) -> 冷凍 | P23: =VLOOKUP($A23,订货1!$A23:$E264,5,0) -> 1kg*10pkt | Q23: =VLOOKUP($A23,订货1!$A23:$F264,6,0) -> 箱 | R23: =IF(ROUNDUP(W23-Y23-X23,0)>=0,ROUNDUP((W23-Y23-X23),0),0) -> 0 | S23: 全店 | T23: =SUMIF(预估营业额3!$B$3:$B$39,">="&$H$2,预估营业额3!$E$3:$E$39)-SUMIF(预估营业额3!$B$3:$B$39,">"&N23,预估营业额3!$E$3:$E$39) -> 0 | U23: 0.13559038 | V23: 1 | W23: =T23*U23*V23 -> 0 | X23: 1 | Y23: =Z23+AA23 -> 0 | AF23: 1 | AJ23: 1 | AM23: 1 | AO23: 1 | BG23: =VLOOKUP($A23,订货1!$A23:$I264,9,0) -> 由仓库 | BH23: =VLOOKUP($A23,订货1!$A23:$H264,8,0) -> 丹东永明食品有限公司
A24: 101030 | B24: 海鲜味调味汁 | C24: 冷凍 | E24: 2kg*5pc | F24: 箱 | G24: 嘉兴铃吉食品有限公司 | H24: 嘉兴铃吉食品有限公司 | I24: 由仓库 | J24: 091永德生活广场店（松江） | K24: =VLOOKUP($A24,订货1!$A24:$A265,1,0) -> 101030 | L24: =VLOOKUP($A24,订货1!$A24:$G265,7,0) -> 嘉兴铃吉食品有限公司 | M24: =VLOOKUP($A24,订货1!$A24:$B265,2,0) -> 海鲜味调味汁 | N24: =$N$4 -> 45978 | O24: =VLOOKUP($A24,订货1!$A24:$C265,3,0) -> 冷凍 | P24: =VLOOKUP($A24,订货1!$A24:$E265,5,0) -> 2kg*5pc | Q24: =VLOOKUP($A24,订货1!$A24:$F265,6,0) -> 箱 | R24: =IF(ROUNDUP(W24-Y24-X24,0)>=0,ROUNDUP((W24-Y24-X24),0),0) -> 0 | S24: 全店 | T24: =SUMIF(预估营业额3!$B$3:$B$39,">="&$H$2,预估营业额3!$E$3:$E$39)-SUMIF(预估营业额3!$B$3:$B$39,">"&N24,预估营业额3!$E$3:$E$39) -> 0 | U24: 0.10316051 | V24: 1 | W24: =T24*U24*V24 -> 0 | X24: 1 | Y24: =Z24+AA24 -> 1 | Z24: 1 | AG24: 1 | AI24: 1 | AN24: 1 | BG24: =VLOOKUP($A24,订货1!$A24:$I265,9,0) -> 由仓库 | BH24: =VLOOKUP($A24,订货1!$A24:$H265,8,0) -> 嘉兴铃吉食品有限公司
A25: 101055 | B25: 蔬菜汤 | C25: 冷凍 | E25: 1kg*10pc | F25: 箱 | G25: 嘉兴铃吉食品有限公司 | H25: 嘉兴铃吉食品有限公司 | I25: 由仓库 | J25: 092新龙阳广场 | K25: =VLOOKUP($A25,订货1!$A25:$A266,1,0) -> 101055 | L25: =VLOOKUP($A25,订货1!$A25:$G266,7,0) -> 嘉兴铃吉食品有限公司 | M25: =VLOOKUP($A25,订货1!$A25:$B266,2,0) -> 蔬菜汤 | N25: =$N$4 -> 45978 | O25: =VLOOKUP($A25,订货1!$A25:$C266,3,0) -> 冷凍 | P25: =VLOOKUP($A25,订货1!$A25:$E266,5,0) -> 1kg*10pc | Q25: =VLOOKUP($A25,订货1!$A25:$F266,6,0) -> 箱 | R25: =IF(ROUNDUP(W25-Y25-X25,0)>=0,ROUNDUP((W25-Y25-X25),0),0) -> 0 | S25: 全店 | T25: =SUMIF(预估营业额3!$B$3:$B$39,">="&$H$2,预估营业额3!$E$3:$E$39)-SUMIF(预估营业额3!$B$3:$B$39,">"&N25,预估营业额3!$E$3:$E$39) -> 0 | U25: 0.072687625 | V25: 1 | W25: =T25*U25*V25 -> 0 | X25: 1 | Y25: =Z25+AA25 -> 0 | AF25: 1 | AM25: 1 | BG25: =VLOOKUP($A25,订货1!$A25:$I266,9,0) -> 由仓库 | BH25: =VLOOKUP($A25,订货1!$A25:$H266,8,0) -> 嘉兴铃吉食品有限公司
A26: 101597 | B26: 黑胡椒酱 | C26: 冷凍 | E26: 1kg*10pc | F26: 箱 | G26: 嘉兴铃吉食品有限公司 | H26: 嘉兴铃吉食品有限公司 | I26: 由仓库 | J26: 096莲花广场 | K26: =VLOOKUP($A26,订货1!$A26:$A267,1,0) -> 101597 | L26: =VLOOKUP($A26,订货1!$A26:$G267,7,0) -> 嘉兴铃吉食品有限公司 | M26: =VLOOKUP($A26,订货1!$A26:$B267,2,0) -> 黑胡椒酱 | N26: =$N$4 -> 45978 | O26: =VLOOKUP($A26,订货1!$A26:$C267,3,0) -> 冷凍 | P26: =VLOOKUP($A26,订货1!$A26:$E267,5,0) -> 1kg*10pc | Q26: =VLOOKUP($A26,订货1!$A26:$F267,6,0) -> 箱 | R26: =IF(ROUNDUP(W26-Y26-X26,0)>=0,ROUNDUP((W26-Y26-X26),0),0) -> 0 | S26: 全店 | T26: =SUMIF(预估营业额3!$B$3:$B$39,">="&$H$2,预估营业额3!$E$3:$E$39)-SUMIF(预估营业额3!$B$3:$B$39,">"&N26,预估营业额3!$E$3:$E$39) -> 0 | U26: 0.078278981 | V26: 1.1 | W26: =T26*U26*V26 -> 0 | X26: 1 | Y26: =Z26+AA26 -> 0 | AG26: 1 | AM26: 1 | BG26: =VLOOKUP($A26,订货1!$A26:$I267,9,0) -> 由仓库 | BH26: =VLOOKUP($A26,订货1!$A26:$H267,8,0) -> 嘉兴铃吉食品有限公司
A27: 101769 | B27: 扁可颂面包 | C27: 常温 | E27: 20g*50pc | F27: 箱 | G27: 杭州洲际食品有限公司 | H27: 杭州洲际食品有限公司 | I27: 由仓库 | J27: 097苏州泉屋百货 | K27: =VLOOKUP($A27,订货1!$A27:$A268,1,0) -> 101769 | L27: =VLOOKUP($A27,订货1!$A27:$G268,7,0) -> 杭州洲际食品有限公司 | M27: =VLOOKUP($A27,订货1!$A27:$B268,2,0) -> 扁可颂面包 | N27: =$N$4 -> 45978 | O27: =VLOOKUP($A27,订货1!$A27:$C268,3,0) -> 常温 | P27: =VLOOKUP($A27,订货1!$A27:$E268,5,0) -> 20g*50pc | Q27: =VLOOKUP($A27,订货1!$A27:$F268,6,0) -> 箱 | R27: =IF(ROUNDUP(W27-Y27-X27,0)>=0,ROUNDUP((W27-Y27-X27),0),0) -> 0 | S27: 实验店 | T27: =SUMIF(预估营业额3!$B$3:$B$39,">="&$H$2,预估营业额3!$E$3:$E$39)-SUMIF(预估营业额3!$B$3:$B$39,">"&N27,预估营业额3!$E$3:$E$39) -> 0 | U27: 0 | V27: 1 | W27: =T27*U27*V27 -> 0 | X27: 0 | Y27: =Z27+AA27 -> 0 | BG27: =VLOOKUP($A27,订货1!$A27:$I268,9,0) -> 由仓库 | BH27: =VLOOKUP($A27,订货1!$A27:$H268,8,0) -> 杭州洲际食品有限公司
A28: 101508 | B28: 肉酱 | C28: 冷凍 | E28: 1kg*10pc | F28: 箱 | G28: 嘉兴铃吉食品有限公司 | H28: 嘉兴铃吉食品有限公司 | I28: 由仓库 | J28: 099苏州永旺店 | K28: =VLOOKUP($A28,订货1!$A28:$A269,1,0) -> 101508 | L28: =VLOOKUP($A28,订货1!$A28:$G269,7,0) -> 嘉兴铃吉食品有限公司 | M28: =VLOOKUP($A28,订货1!$A28:$B269,2,0) -> 肉酱 | N28: =$N$4 -> 45978 | O28: =VLOOKUP($A28,订货1!$A28:$C269,3,0) -> 冷凍 | P28: =VLOOKUP($A28,订货1!$A28:$E269,5,0) -> 1kg*10pc | Q28: =VLOOKUP($A28,订货1!$A28:$F269,6,0) -> 箱 | R28: =IF(ROUNDUP(W28-Y28-X28,0)>=0,ROUNDUP((W28-Y28-X28),0),0) -> 0 | S28: 2地域 | T28: =SUMIF(预估营业额3!$B$3:$B$39,">="&$H$2,预估营业额3!$E$3:$E$39)-SUMIF(预估营业额3!$B$3:$B$39,">"&N28,预估营业额3!$E$3:$E$39) -> 0 | U28: 0 | V28: 1.1 | W28: =T28*U28*V28 -> 0 | X28: 0 | Y28: =Z28+AA28 -> 0 | BG28: =VLOOKUP($A28,订货1!$A28:$I269,9,0) -> 由仓库 | BH28: =VLOOKUP($A28,订货1!$A28:$H269,8,0) -> 嘉兴铃吉食品有限公司
A29: 101347 | B29: 雪碧糖浆 | C29: 常温 | E29: 10L | F29: 箱 | G29: 上海申美饮料食品有限公司 | H29: 上海申美饮料食品有限公司 | I29: 由仓库 | J29: 101松江万达（松江） | K29: =VLOOKUP($A29,订货1!$A29:$A270,1,0) -> 101347 | L29: =VLOOKUP($A29,订货1!$A29:$G270,7,0) -> 上海申美饮料食品有限公司 | M29: =VLOOKUP($A29,订货1!$A29:$B270,2,0) -> 雪碧糖浆 | N29: =$N$4 -> 45978 | O29: =VLOOKUP($A29,订货1!$A29:$C270,3,0) -> 常温 | P29: =VLOOKUP($A29,订货1!$A29:$E270,5,0) -> 10L | Q29: =VLOOKUP($A29,订货1!$A29:$F270,6,0) -> 箱 | R29: =IF(ROUNDUP(W29-Y29-X29,0)>=0,ROUNDUP((W29-Y29-X29),0),0) -> 0 | S29: 其它 | T29: =SUMIF(预估营业额3!$B$3:$B$39,">="&$H$2,预估营业额3!$E$3:$E$39)-SUMIF(预估营业额3!$B$3:$B$39,">"&N29,预估营业额3!$E$3:$E$39) -> 0 | U29: 0.062902752 | V29: 1 | W29: =T29*U29*V29 -> 0 | X29: 1 | Y29: =Z29+AA29 -> 0 | AB29: 1 | AI29: 1 | BG29: =VLOOKUP($A29,订货1!$A29:$I270,9,0) -> 由仓库 | BH29: =VLOOKUP($A29,订货1!$A29:$H270,8,0) -> 上海申美饮料食品有限公司
A30: 101348 | B30: 飞想茶糖浆 | C30: 常温 | E30: 10L | F30: 箱 | G30: 上海申美饮料食品有限公司 | H30: 上海申美饮料食品有限公司 | I30: 由仓库 | J30: 102新紫茂广场 | K30: =VLOOKUP($A30,订货1!$A30:$A271,1,0) -> 101348 | L30: =VLOOKUP($A30,订货1!$A30:$G271,7,0) -> 上海申美饮料食品有限公司 | M30: =VLOOKUP($A30,订货1!$A30:$B271,2,0) -> 飞想茶糖浆 | N30: =$N$4 -> 45978 | O30: =VLOOKUP($A30,订货1!$A30:$C271,3,0) -> 常温 | P30: =VLOOKUP($A30,订货1!$A30:$E271,5,0) -> 10L | Q30: =VLOOKUP($A30,订货1!$A30:$F271,6,0) -> 箱 | R30: =IF(ROUNDUP(W30-Y30-X30,0)>=0,ROUNDUP((W30-Y30-X30),0),0) -> 0 | S30: 其它 | T30: =SUMIF(预估营业额3!$B$3:$B$39,">="&$H$2,预估营业额3!$E$3:$E$39)-SUMIF(预估营业额3!$B$3:$B$39,">"&N30,预估营业额3!$E$3:$E$39) -> 0 | U30: 0.047526524 | V30: 1 | W30: =T30*U30*V30 -> 0 | X30: 1 | Y30: =Z30+AA30 -> 0 | AB30: 1 | AL30: 1 | BG30: =VLOOKUP($A30,订货1!$A30:$I271,9,0) -> 由仓库 | BH30: =VLOOKUP($A30,订货1!$A30:$H271,8,0) -> 上海申美饮料食品有限公司
A31: 101355 | B31: 可乐糖浆 | C31: 常温 | E31: 20L | F31: 箱 | G31: 上海申美饮料食品有限公司 | H31: 上海申美饮料食品有限公司 | I31: 由仓库 | J31: 103嘉定同济广场 | K31: =VLOOKUP($A31,订货1!$A31:$A272,1,0) -> 101355 | L31: =VLOOKUP($A31,订货1!$A31:$G272,7,0) -> 上海申美饮料食品有限公司 | M31: =VLOOKUP($A31,订货1!$A31:$B272,2,0) -> 可乐糖浆 | N31: =$N$4 -> 45978 | O31: =VLOOKUP($A31,订货1!$A31:$C272,3,0) -> 常温 | P31: =VLOOKUP($A31,订货1!$A31:$E272,5,0) -> 20L | Q31: =VLOOKUP($A31,订货1!$A31:$F272,6,0) -> 箱 | R31: =IF(ROUNDUP(W31-Y31-X31,0)>=0,ROUNDUP((W31-Y31-X31),0),0) -> 0 | S31: 其它 | T31: =SUMIF(预估营业额3!$B$3:$B$39,">="&$H$2,预估营业额3!$E$3:$E$39)-SUMIF(预估营业额3!$B$3:$B$39,">"&N31,预估营业额3!$E$3:$E$39) -> 0 | U31: 0.068494108 | V31: 1 | W31: =T31*U31*V31 -> 0 | X31: 0 | Y31: =Z31+AA31 -> 0 | AE31: 1 | AO31: 1 | BG31: =VLOOKUP($A31,订货1!$A31:$I272,9,0) -> 由仓库 | BH31: =VLOOKUP($A31,订货1!$A31:$H272,8,0) -> 上海申美饮料食品有限公司
A32: 101356 | B32: 芬达糖浆 | C32: 常温 | E32: 10L | F32: 箱 | G32: 上海申美饮料食品有限公司 | H32: 上海申美饮料食品有限公司 | I32: 由仓库 | J32: 107苏州人民路店 | K32: =VLOOKUP($A32,订货1!$A32:$A273,1,0) -> 101356 | L32: =VLOOKUP($A32,订货1!$A32:$G273,7,0) -> 上海申美饮料食品有限公司 | M32: =VLOOKUP($A32,订货1!$A32:$B273,2,0) -> 芬达糖浆 | N32: =$N$4 -> 45978 | O32: =VLOOKUP($A32,订货1!$A32:$C273,3,0) -> 常温 | P32: =VLOOKUP($A32,订货1!$A32:$E273,5,0) -> 10L | Q32: =VLOOKUP($A32,订货1!$A32:$F273,6,0) -> 箱 | R32: =IF(ROUNDUP(W32-Y32-X32,0)>=0,ROUNDUP((W32-Y32-X32),0),0) -> 0 | S32: 其它 | T32: =SUMIF(预估营业额3!$B$3:$B$39,">="&$H$2,预估营业额3!$E$3:$E$39)-SUMIF(预估营业额3!$B$3:$B$39,">"&N32,预估营业额3!$E$3:$E$39) -> 0 | U32: 0.05311788 | V32: 1 | W32: =T32*U32*V32 -> 0 | X32: 1 | Y32: =Z32+AA32 -> 0 | AH32: 1 | BG32: =VLOOKUP($A32,订货1!$A32:$I273,9,0) -> 由仓库 | BH32: =VLOOKUP($A32,订货1!$A32:$H273,8,0) -> 上海申美饮料食品有限公司
A33: 101483 | B33: 柠檬+C糖浆 | C33: 常温 | E33: 10L | F33: 箱 | G33: 上海申美饮料食品有限公司 | H33: 上海申美饮料食品有限公司 | I33: 由仓库 | J33: 108近铁广场 | K33: =VLOOKUP($A33,订货1!$A33:$A274,1,0) -> 101483 | L33: =VLOOKUP($A33,订货1!$A33:$G274,7,0) -> 上海申美饮料食品有限公司 | M33: =VLOOKUP($A33,订货1!$A33:$B274,2,0) -> 柠檬+C糖浆 | N33: =$N$4 -> 45978 | O33: =VLOOKUP($A33,订货1!$A33:$C274,3,0) -> 常温 | P33: =VLOOKUP($A33,订货1!$A33:$E274,5,0) -> 10L | Q33: =VLOOKUP($A33,订货1!$A33:$F274,6,0) -> 箱 | R33: =IF(ROUNDUP(W33-Y33-X33,0)>=0,ROUNDUP((W33-Y33-X33),0),0) -> 0 | S33: 其它 | T33: =SUMIF(预估营业额3!$B$3:$B$39,">="&$H$2,预估营业额3!$E$3:$E$39)-SUMIF(预估营业额3!$B$3:$B$39,">"&N33,预估营业额3!$E$3:$E$39) -> 0 | U33: 0.044730846 | V33: 1 | W33: =T33*U33*V33 -> 0 | X33: 1 | Y33: =Z33+AA33 -> 0 | AF33: 1 | AJ33: 1 | BG33: =VLOOKUP($A33,订货1!$A33:$I274,9,0) -> 由仓库 | BH33: =VLOOKUP($A33,订货1!$A33:$H274,8,0) -> 上海申美饮料食品有限公司
A34: 700000 | B34: 申美碳酸 | C34: 常温 | E34: 10L | F34: 桶 | G34: 上海申美饮料食品有限公司 | H34: 上海申美饮料食品有限公司 | I34: 由厂商 | J34: 109青浦吾悦广场 | K34: =VLOOKUP($A34,订货1!$A34:$A275,1,0) -> 700000 | L34: =VLOOKUP($A34,订货1!$A34:$G275,7,0) -> 上海申美饮料食品有限公司 | M34: =VLOOKUP($A34,订货1!$A34:$B275,2,0) -> 申美碳酸 | O34: =VLOOKUP($A34,订货1!$A34:$C275,3,0) -> 常温 | P34: =VLOOKUP($A34,订货1!$A34:$E275,5,0) -> 10L | Q34: =VLOOKUP($A34,订货1!$A34:$F275,6,0) -> 桶 | R34: =IF(ROUNDUP(W34-Y34-X34,0)>=0,ROUNDUP((W34-Y34-X34),0),0) -> 0 | S34: 其它 | T34: =SUMIF(预估营业额3!$B$3:$B$39,">="&$H$2,预估营业额3!$E$3:$E$39)-SUMIF(预估营业额3!$B$3:$B$39,">"&N34,预估营业额3!$E$3:$E$39) -> 38.3 | U34: 0.013978389 | V34: 1 | W34: =T34*U34*V34 -> 0.53537231 | X34: 2 | Y34: =Z34+AA34 -> 0 | BG34: =VLOOKUP($A34,订货1!$A34:$I275,9,0) -> 由厂商 | BH34: =VLOOKUP($A34,订货1!$A34:$H275,8,0) -> 上海申美饮料食品有限公司
A35: 730003 | B35: 樱桃番茄 | C35: 冷蔵 | E35: 0.5kg | F35: 袋 | G35: 赛沛弗科技发展（浙江）有限公司 | H35: 上海亚太国际蔬菜有限公司 | I35: 由厂商 | J35: 110无锡T12 | K35: =VLOOKUP($A35,订货1!$A35:$A276,1,0) -> 730003 | L35: =VLOOKUP($A35,订货1!$A35:$G276,7,0) -> 赛沛弗科技发展（浙江）有限公司 | M35: =VLOOKUP($A35,订货1!$A35:$B276,2,0) -> 樱桃番茄 | O35: =VLOOKUP($A35,订货1!$A35:$C276,3,0) -> 冷蔵 | P35: =VLOOKUP($A35,订货1!$A35:$E276,5,0) -> 0.5kg | Q35: =VLOOKUP($A35,订货1!$A35:$F276,6,0) -> 袋 | R35: =IF(ROUNDUP(W35-Y35-X35,0)>=0,ROUNDUP((W35-Y35-X35),0),0) -> 0 | S35: 其它 | T35: =SUMIF(预估营业额3!$B$3:$B$39,">="&$H$2,预估营业额3!$E$3:$E$39)-SUMIF(预估营业额3!$B$3:$B$39,">"&N35,预估营业额3!$E$3:$E$39) -> 38.3 | U35: 0 | V35: 1 | W35: =T35*U35*V35 -> 0 | X35: 0 | Y35: =Z35+AA35 -> 0 | BG35: =VLOOKUP($A35,订货1!$A35:$I276,9,0) -> 由厂商 | BH35: =VLOOKUP($A35,订货1!$A35:$H276,8,0) -> 上海亚太国际蔬菜有限公司
A36: 730004 | B36: 彩椒丝 | C36: 冷蔵 | E36: 0.2kg | F36: 袋 | G36: 赛沛弗科技发展（浙江）有限公司 | H36: 上海亚太国际蔬菜有限公司 | I36: 由厂商 | J36: 111家乐福高青路店 | K36: =VLOOKUP($A36,订货1!$A36:$A277,1,0) -> 730004 | L36: =VLOOKUP($A36,订货1!$A36:$G277,7,0) -> 赛沛弗科技发展（浙江）有限公司 | M36: =VLOOKUP($A36,订货1!$A36:$B277,2,0) -> 彩椒丝 | N36: =$N$35 -> 0 | O36: =VLOOKUP($A36,订货1!$A36:$C277,3,0) -> 冷蔵 | P36: =VLOOKUP($A36,订货1!$A36:$E277,5,0) -> 0.2kg | Q36: =VLOOKUP($A36,订货1!$A36:$F277,6,0) -> 袋 | R36: =IF(ROUNDUP(W36-Y36-X36,0)>=0,ROUNDUP((W36-Y36-X36),0),0) -> 0 | S36: 实验店 | T36: =SUMIF(预估营业额3!$B$3:$B$39,">="&$H$2,预估营业额3!$E$3:$E$39)-SUMIF(预估营业额3!$B$3:$B$39,">"&N36,预估营业额3!$E$3:$E$39) -> -39.438 | U36: 0 | V36: 1 | W36: =T36*U36*V36 -> 0 | X36: 0 | Y36: =Z36+AA36 -> 0 | BG36: =VLOOKUP($A36,订货1!$A36:$I277,9,0) -> 由厂商 | BH36: =VLOOKUP($A36,订货1!$A36:$H277,8,0) -> 上海亚太国际蔬菜有限公司
A37: 730005 | B37: 蔬菜底料 | C37: 冷蔵 | E37: 1kg | F37: 袋 | G37: 赛沛弗科技发展（浙江）有限公司 | H37: 上海盛科果蔬专业合作社 | I37: 由厂商 | J37: 112苏州观前街食百家美食广场 | K37: =VLOOKUP($A37,订货1!$A37:$A278,1,0) -> 730005 | L37: =VLOOKUP($A37,订货1!$A37:$G278,7,0) -> 赛沛弗科技发展（浙江）有限公司 | M37: =VLOOKUP($A37,订货1!$A37:$B278,2,0) -> 蔬菜底料 | N37: =$N$35 -> 0 | O37: =VLOOKUP($A37,订货1!$A37:$C278,3,0) -> 冷蔵 | P37: =VLOOKUP($A37,订货1!$A37:$E278,5,0) -> 1kg | Q37: =VLOOKUP($A37,订货1!$A37:$F278,6,0) -> 袋 | R37: =IF(ROUNDUP(W37-Y37-X37,0)>=0,ROUNDUP((W37-Y37-X37),0),0) -> 0 | S37: 其它 | T37: =SUMIF(预估营业额3!$B$3:$B$39,">="&$H$2,预估营业额3!$E$3:$E$39)-SUMIF(预估营业额3!$B$3:$B$39,">"&N37,预估营业额3!$E$3:$E$39) -> -39.438 | U37: 0 | V37: 1 | W37: =T37*U37*V37 -> 0 | X37: 0 | Y37: =Z37+AA37 -> 0 | BG37: =VLOOKUP($A37,订货1!$A37:$I278,9,0) -> 由厂商 | BH37: =VLOOKUP($A37,订货1!$A37:$H278,8,0) -> 上海盛科果蔬专业合作社
A38: 730006 | B38: 脆爽沙拉 | C38: 冷蔵 | E38: 1kg | F38: 袋 | G38: 赛沛弗科技发展（浙江）有限公司 | H38: 上海亚太国际蔬菜有限公司 | I38: 由厂商 | J38: 113上蔬永辉 | K38: =VLOOKUP($A38,订货1!$A38:$A279,1,0) -> 730006 | L38: =VLOOKUP($A38,订货1!$A38:$G279,7,0) -> 赛沛弗科技发展（浙江）有限公司 | M38: =VLOOKUP($A38,订货1!$A38:$B279,2,0) -> 脆爽沙拉 | N38: =$N$35 -> 0 | O38: =VLOOKUP($A38,订货1!$A38:$C279,3,0) -> 冷蔵 | P38: =VLOOKUP($A38,订货1!$A38:$E279,5,0) -> 1kg | Q38: =VLOOKUP($A38,订货1!$A38:$F279,6,0) -> 袋 | R38: =IF(ROUNDUP(W38-Y38-X38,0)>=0,ROUNDUP((W38-Y38-X38),0),0) -> 0 | S38: 其它 | T38: =SUMIF(预估营业额3!$B$3:$B$39,">="&$H$2,预估营业额3!$E$3:$E$39)-SUMIF(预估营业额3!$B$3:$B$39,">"&N38,预估营业额3!$E$3:$E$39) -> -39.438 | U38: 0 | V38: 1 | W38: =T38*U38*V38 -> 0 | Y38: =Z38+AA38 -> 0 | BG38: =VLOOKUP($A38,订货1!$A38:$I279,9,0) -> 由厂商 | BH38: =VLOOKUP($A38,订货1!$A38:$H279,8,0) -> 上海亚太国际蔬菜有限公司
A39: 730018 | B39: 小青菜 | C39: 冷蔵 | E39: 0.5kg | F39: 袋 | G39: 赛沛弗科技发展（浙江）有限公司 | H39: 上海亚太国际蔬菜有限公司 | I39: 由厂商 | J39: 114鑫都广场 | K39: =VLOOKUP($A39,订货1!$A39:$A280,1,0) -> 730018 | L39: =VLOOKUP($A39,订货1!$A39:$G280,7,0) -> 赛沛弗科技发展（浙江）有限公司 | M39: =VLOOKUP($A39,订货1!$A39:$B280,2,0) -> 小青菜 | N39: =$N$35 -> 0 | O39: =VLOOKUP($A39,订货1!$A39:$C280,3,0) -> 冷蔵 | P39: =VLOOKUP($A39,订货1!$A39:$E280,5,0) -> 0.5kg | Q39: =VLOOKUP($A39,订货1!$A39:$F280,6,0) -> 袋 | R39: =IF(ROUNDUP(W39-Y39-X39,0)>=0,ROUNDUP((W39-Y39-X39),0),0) -> 0 | S39: 其它 | T39: =SUMIF(预估营业额3!$B$3:$B$39,">="&$H$2,预估营业额3!$E$3:$E$39)-SUMIF(预估营业额3!$B$3:$B$39,">"&N39,预估营业额3!$E$3:$E$39) -> -39.438 | U39: 0 | V39: 1 | W39: =T39*U39*V39 -> 0 | Y39: =Z39+AA39 -> 0 | BG39: =VLOOKUP($A39,订货1!$A39:$I280,9,0) -> 由厂商 | BH39: =VLOOKUP($A39,订货1!$A39:$H280,8,0) -> 上海亚太国际蔬菜有限公司
A40: 730008 | B40: 猕猴桃 | C40: 冷蔵 | E40: 0.08kg | F40: 个 | G40: 赛沛弗科技发展（浙江）有限公司 | H40: 上海盛科果蔬专业合作社 | I40: 由厂商 | J40: 115殷高西路店 | K40: =VLOOKUP($A40,订货1!$A40:$A281,1,0) -> 730008 | L40: =VLOOKUP($A40,订货1!$A40:$G281,7,0) -> 赛沛弗科技发展（浙江）有限公司 | M40: =VLOOKUP($A40,订货1!$A40:$B281,2,0) -> 猕猴桃 | N40: =$N$35 -> 0 | O40: =VLOOKUP($A40,订货1!$A40:$C281,3,0) -> 冷蔵 | P40: =VLOOKUP($A40,订货1!$A40:$E281,5,0) -> 0.08kg | Q40: =VLOOKUP($A40,订货1!$A40:$F281,6,0) -> 个 | R40: =IF(ROUNDUP(W40-Y40-X40,0)>=0,ROUNDUP((W40-Y40-X40),0),0) -> 0 | S40: 其它 | T40: =SUMIF(预估营业额3!$B$3:$B$39,">="&$H$2,预估营业额3!$E$3:$E$39)-SUMIF(预估营业额3!$B$3:$B$39,">"&N40,预估营业额3!$E$3:$E$39) -> -39.438 | U40: 0 | V40: 1 | W40: =T40*U40*V40 -> 0 | Y40: =Z40+AA40 -> 0 | BG40: =VLOOKUP($A40,订货1!$A40:$I281,9,0) -> 由厂商 | BH40: =VLOOKUP($A40,订货1!$A40:$H281,8,0) -> 上海盛科果蔬专业合作社
...

Sheet 店铺收货台帐2
B1: 注意事项：①数量将从“订货1”自动导入。②生产日期、保质期按实际填写（填写方法如下:2019/1/21）。 | DH1: 店营业额↓
B2: ③盘库未开封最小原始包装单位（即：Ｅ列末尾标示单位→袋、瓶、罐、块） | I2: 1日 | L2: 2日 | O2: =订货1!AB3+2 -> 45964 | R2: =O2+1 -> 45965 | U2: =R2+1 -> 45966 | X2: =U2+1 -> 45967 | AA2: =X2+1 -> 45968 | AD2: =AA2+1 -> 45969 | AG2: =AD2+1 -> 45970 | AJ2: =AG2+1 -> 45971 | AM2: =AJ2+1 -> 45972 | AP2: =AM2+1 -> 45973 | AS2: =AP2+1 -> 45974 | AV2: =AS2+1 -> 45975 | AY2: =AV2+1 -> 45976 | BB2: =AY2+1 -> 45977 | BE2: =BB2+1 -> 45978 | BH2: =BE2+1 -> 45979 | BK2: =BH2+1 -> 45980 | BN2: =BK2+1 -> 45981 | BQ2: =BN2+1 -> 45982 | BT2: =BQ2+1 -> 45983 | BW2: =BT2+1 -> 45984 | BZ2: =BW2+1 -> 45985 | CC2: =BZ2+1 -> 45986 | CF2: =CC2+1 -> 45987 | CI2: =CF2+1 -> 45988 | CL2: =CI2+1 -> 45989 | CO2: =CL2+1 -> 45990 | CR2: =CO2+1 -> 45991 | CU2: =CR2+1 -> 45992 | CX2: =CU2+1 -> 45993 | DA2: =CX2+1 -> 45994
B3: 供应商名称 | D3: 商品名称 | E3: 规格 | F3: 单位 | G3: 本月盘库数 | H3: 合计 | I3: 数量 | J3: 生产日期 | K3: 保质期 | L3: 数量 | M3: 生产日期 | N3: 保质期 | O3: 数量 | P3: 生产日期 | Q3: 保质期 | R3: 数量 | S3: 生产日期 | T3: 保质期 | U3: 数量 | V3: 生产日期 | W3: 保质期 | X3: 数量 | Y3: 生产日期 | Z3: 保质期 | AA3: 数量 | AB3: 生产日期 | AC3: 保质期 | AD3: 数量 | AE3: 生产日期 | AF3: 保质期 | AG3: 数量 | AH3: 生产日期 | AI3: 保质期 | AJ3: 数量 | AK3: 生产日期 | AL3: 保质期 | AM3: 数量 | AN3: 生产日期 | AO3: 保质期 | AP3: 数量 | AQ3: 生产日期 | AR3: 保质期 | AS3: 数量 | AT3: 生产日期 | AU3: 保质期 | AV3: 数量 | AW3: 生产日期 | AX3: 保质期 | AY3: 数量 | AZ3: 生产日期 | BA3: 保质期 | BB3: 数量 | BC3: 生产日期 | BD3: 保质期 | BE3: 数量 | BF3: 生产日期 | BG3: 保质期 | BH3: 数量 | BI3: 生产日期 | BJ3: 保质期 | BK3: 数量 | BL3: 生产日期 | BM3: 保质期 | BN3: 数量 | BO3: 生产日期 | BP3: 保质期 | BQ3: 数量 | BR3: 生产日期 | BS3: 保质期 | BT3: 数量 | BU3: 生产日期 | BV3: 保质期 | BW3: 数量 | BX3: 生产日期 | BY3: 保质期 | BZ3: 数量 | CA3: 生产日期 | CB3: 保质期 | CC3: 数量 | CD3: 生产日期 | CE3: 保质期 | CF3: 数量 | CG3: 生产日期 | CH3: 保质期 | CI3: 数量 | CJ3: 生产日期 | CK3: 保质期 | CL3: 数量 | CM3: 生产日期 | CN3: 保质期 | CO3: 数量 | CP3: 生产日期 | CQ3: 保质期 | CR3: 数量 | CS3: 生产日期 | CT3: 保质期 | CU3: 数量 | CV3: 生产日期 | CW3: 保质期 | CX3: 数量 | CY3: 生产日期 | CZ3: 保质期 | DA3: 数量 | DB3: 生产日期 | DC3: 保质期 | DD3: 上月盘库数 | DE3: 本月盘库数 | DF3: 月实用 | DG3: 单位 | DH3: 万元使用量
A4: =订货1!A4 -> 101729 | B4: =VLOOKUP($A4,订货1!$A4:$G243,7,0) -> 熠沣实业（上海）有限公司 | C4: =VLOOKUP($A4,订货1!$A4:$H243,8,0) -> 启东欧瑞食品有限公司 | D4: =VLOOKUP($A4,订货1!$A4:$B243,2,0) -> 可可粉 | E4: =VLOOKUP($A4,订货1!$A4:$E243,5,0) -> 0.5kg | F4: =VLOOKUP($A4,订货1!$A4:$F243,6,0) -> 包 | H4: =O4+R4+X4+AA4+AD4+AG4+AJ4+AM4+AP4+AS4+AV4+AY4+BB4+BE4+BH4+BK4+BN4+BQ4+BT4+BW4+BZ4+CC4+CF4+CI4+CL4+CO4+CR4+U4+I4+L4 -> 0 | O4: =订货1!AB4 -> 0 | R4: =订货1!AC4 -> 0 | U4: =订货1!AD4 -> 0 | X4: =订货1!AE4 -> 0 | AA4: =订货1!AF4 -> 0 | AD4: =订货1!AG4 -> 0 | AG4: =订货1!AH4 -> 0 | AJ4: =订货1!AI4 -> 0 | AM4: =订货1!AJ4 -> 0 | AP4: =订货1!AK4 -> 0 | AS4: =订货1!AL4 -> 0 | AV4: =订货1!AM4 -> 0 | AY4: =订货1!AN4 -> 0 | BB4: =订货1!AO4 -> 0 | BE4: =订货1!AP4 -> 0 | BH4: =订货1!AQ4 -> 0 | BK4: =订货1!AR4 -> 0 | BN4: =订货1!AS4 -> 0 | BQ4: =订货1!AT4 -> 0 | BT4: =订货1!AU4 -> 0 | BW4: =订货1!AV4 -> 0 | BZ4: =订货1!AW4 -> 0 | CC4: =订货1!AX4 -> 0 | CF4: =订货1!AY4 -> 0 | CI4: =订货1!AZ4 -> 0 | CL4: =订货1!BA4 -> 0 | CO4: =订货1!BB4 -> 0 | CR4: =订货1!BC4 -> 0 | CU4: =订货1!BD4 -> 0 | CX4: =订货1!BE4 -> 0 | DA4: =订货1!BF4 -> 0 | DD4: 0 | DE4: =INT(G4/DI4) -> #DIV/0! | DF4: =IFERROR(DD4+H4-G4,"") -> 0 | DG4: =订货1!$Q4 -> 包 | DH4: =DF4/($DH$2/10000) -> #DIV/0!
A5: =订货1!A5 -> 101727 | B5: =VLOOKUP($A5,订货1!$A5:$G244,7,0) -> 青岛亚是加食品有限公司 | C5: =VLOOKUP($A5,订货1!$A5:$H244,8,0) -> 青岛亚是加食品有限公司 | D5: =VLOOKUP($A5,订货1!$A5:$B244,2,0) -> 冷冻意大利面 | E5: =VLOOKUP($A5,订货1!$A5:$E244,5,0) -> 200g*30 | F5: =VLOOKUP($A5,订货1!$A5:$F244,6,0) -> 箱 | H5: =O5+R5+X5+AA5+AD5+AG5+AJ5+AM5+AP5+AS5+AV5+AY5+BB5+BE5+BH5+BK5+BN5+BQ5+BT5+BW5+BZ5+CC5+CF5+CI5+CL5+CO5+CR5+U5+I5+L5 -> 0 | O5: =订货1!AB5 -> 0 | R5: =订货1!AC5 -> 0 | U5: =订货1!AD5 -> 0 | X5: =订货1!AE5 -> 0 | AA5: =订货1!AF5 -> 0 | AD5: =订货1!AG5 -> 0 | AG5: =订货1!AH5 -> 0 | AJ5: =订货1!AI5 -> 0 | AM5: =订货1!AJ5 -> 0 | AP5: =订货1!AK5 -> 0 | AS5: =订货1!AL5 -> 0 | AV5: =订货1!AM5 -> 0 | AY5: =订货1!AN5 -> 0 | BB5: =订货1!AO5 -> 0 | BE5: =订货1!AP5 -> 0 | BH5: =订货1!AQ5 -> 0 | BK5: =订货1!AR5 -> 0 | BN5: =订货1!AS5 -> 0 | BQ5: =订货1!AT5 -> 0 | BT5: =订货1!AU5 -> 0 | BW5: =订货1!AV5 -> 0 | BZ5: =订货1!AW5 -> 0 | CC5: =订货1!AX5 -> 0 | CF5: =订货1!AY5 -> 0 | CI5: =订货1!AZ5 -> 0 | CL5: =订货1!BA5 -> 0 | CO5: =订货1!BB5 -> 0 | CR5: =订货1!BC5 -> 0 | CU5: =订货1!BD5 -> 0 | CX5: =订货1!BE5 -> 0 | DA5: =订货1!BF5 -> 0 | DD5: 0 | DE5: =INT(G5/DI5) -> #DIV/0! | DF5: =IFERROR(DD5+H5-G5,"") -> 0 | DG5: =订货1!$Q5 -> 箱 | DH5: =DF5/($DH$2/10000) -> #DIV/0!
A6: =订货1!A6 -> 101730 | B6: =VLOOKUP($A6,订货1!$A6:$G245,7,0) -> 卓典食品科技（江苏）有限公司 | C6: =VLOOKUP($A6,订货1!$A6:$H245,8,0) -> 卓典食品科技（江苏）有限公司 | D6: =VLOOKUP($A6,订货1!$A6:$B245,2,0) -> 利梭多粉 | E6: =VLOOKUP($A6,订货1!$A6:$E245,5,0) -> 33g*20包*20袋/箱 | F6: =VLOOKUP($A6,订货1!$A6:$F245,6,0) -> 箱 | H6: =O6+R6+X6+AA6+AD6+AG6+AJ6+AM6+AP6+AS6+AV6+AY6+BB6+BE6+BH6+BK6+BN6+BQ6+BT6+BW6+BZ6+CC6+CF6+CI6+CL6+CO6+CR6+U6+I6+L6 -> 0 | O6: =订货1!AB6 -> 0 | R6: =订货1!AC6 -> 0 | U6: =订货1!AD6 -> 0 | X6: =订货1!AE6 -> 0 | AA6: =订货1!AF6 -> 0 | AD6: =订货1!AG6 -> 0 | AG6: =订货1!AH6 -> 0 | AJ6: =订货1!AI6 -> 0 | AM6: =订货1!AJ6 -> 0 | AP6: =订货1!AK6 -> 0 | AS6: =订货1!AL6 -> 0 | AV6: =订货1!AM6 -> 0 | AY6: =订货1!AN6 -> 0 | BB6: =订货1!AO6 -> 0 | BE6: =订货1!AP6 -> 0 | BH6: =订货1!AQ6 -> 0 | BK6: =订货1!AR6 -> 0 | BN6: =订货1!AS6 -> 0 | BQ6: =订货1!AT6 -> 0 | BT6: =订货1!AU6 -> 0 | BW6: =订货1!AV6 -> 0 | BZ6: =订货1!AW6 -> 0 | CC6: =订货1!AX6 -> 0 | CF6: =订货1!AY6 -> 0 | CI6: =订货1!AZ6 -> 0 | CL6: =订货1!BA6 -> 0 | CO6: =订货1!BB6 -> 0 | CR6: =订货1!BC6 -> 0 | CU6: =订货1!BD6 -> 0 | CX6: =订货1!BE6 -> 0 | DA6: =订货1!BF6 -> 0 | DD6: 0 | DE6: =INT(G6/DI6) -> #DIV/0! | DF6: =IFERROR(DD6+H6-G6,"") -> 0 | DG6: =订货1!$Q6 -> 箱 | DH6: =DF6/($DH$2/10000) -> #DIV/0!
A7: =订货1!A7 -> 101739 | B7: =VLOOKUP($A7,订货1!$A7:$G246,7,0) -> 沈阳华美食品有限公司 | C7: =VLOOKUP($A7,订货1!$A7:$H246,8,0) -> 沈阳华美食品有限公司 | D7: =VLOOKUP($A7,订货1!$A7:$B246,2,0) -> 华美裹粉鸡胗 | E7: =VLOOKUP($A7,订货1!$A7:$E246,5,0) -> 40g*20*12 | F7: =VLOOKUP($A7,订货1!$A7:$F246,6,0) -> 箱 | H7: =O7+R7+X7+AA7+AD7+AG7+AJ7+AM7+AP7+AS7+AV7+AY7+BB7+BE7+BH7+BK7+BN7+BQ7+BT7+BW7+BZ7+CC7+CF7+CI7+CL7+CO7+CR7+U7+I7+L7 -> 0 | O7: =订货1!AB7 -> 0 | R7: =订货1!AC7 -> 0 | U7: =订货1!AD7 -> 0 | X7: =订货1!AE7 -> 0 | AA7: =订货1!AF7 -> 0 | AD7: =订货1!AG7 -> 0 | AG7: =订货1!AH7 -> 0 | AJ7: =订货1!AI7 -> 0 | AM7: =订货1!AJ7 -> 0 | AP7: =订货1!AK7 -> 0 | AS7: =订货1!AL7 -> 0 | AV7: =订货1!AM7 -> 0 | AY7: =订货1!AN7 -> 0 | BB7: =订货1!AO7 -> 0 | BE7: =订货1!AP7 -> 0 | BH7: =订货1!AQ7 -> 0 | BK7: =订货1!AR7 -> 0 | BN7: =订货1!AS7 -> 0 | BQ7: =订货1!AT7 -> 0 | BT7: =订货1!AU7 -> 0 | BW7: =订货1!AV7 -> 0 | BZ7: =订货1!AW7 -> 0 | CC7: =订货1!AX7 -> 0 | CF7: =订货1!AY7 -> 0 | CI7: =订货1!AZ7 -> 0 | CL7: =订货1!BA7 -> 0 | CO7: =订货1!BB7 -> 0 | CR7: =订货1!BC7 -> 0 | CU7: =订货1!BD7 -> 0 | CX7: =订货1!BE7 -> 0 | DA7: =订货1!BF7 -> 0 | DD7: 0 | DE7: =INT(G7/DI7) -> #DIV/0! | DF7: =IFERROR(DD7+H7-G7,"") -> 0 | DG7: =订货1!$Q7 -> 箱 | DH7: =DF7/($DH$2/10000) -> #DIV/0!
A8: =订货1!A8 -> 101752 | B8: =VLOOKUP($A8,订货1!$A8:$G248,7,0) -> 山東三涛食品有限公司 | C8: =VLOOKUP($A8,订货1!$A8:$H248,8,0) -> 山東三涛食品有限公司 | D8: =VLOOKUP($A8,订货1!$A8:$B248,2,0) -> 冷冻土豆泥 | E8: =VLOOKUP($A8,订货1!$A8:$E248,5,0) -> 1kg*10 | F8: =VLOOKUP($A8,订货1!$A8:$F248,6,0) -> 箱 | H8: =O8+R8+X8+AA8+AD8+AG8+AJ8+AM8+AP8+AS8+AV8+AY8+BB8+BE8+BH8+BK8+BN8+BQ8+BT8+BW8+BZ8+CC8+CF8+CI8+CL8+CO8+CR8+U8+I8+L8 -> 0 | O8: =订货1!AB8 -> 0 | R8: =订货1!AC8 -> 0 | U8: =订货1!AD8 -> 0 | X8: =订货1!AE8 -> 0 | AA8: =订货1!AF8 -> 0 | AD8: =订货1!AG8 -> 0 | AG8: =订货1!AH8 -> 0 | AJ8: =订货1!AI8 -> 0 | AM8: =订货1!AJ8 -> 0 | AP8: =订货1!AK8 -> 0 | AS8: =订货1!AL8 -> 0 | AV8: =订货1!AM8 -> 0 | AY8: =订货1!AN8 -> 0 | BB8: =订货1!AO8 -> 0 | BE8: =订货1!AP8 -> 0 | BH8: =订货1!AQ8 -> 0 | BK8: =订货1!AR8 -> 0 | BN8: =订货1!AS8 -> 0 | BQ8: =订货1!AT8 -> 0 | BT8: =订货1!AU8 -> 0 | BW8: =订货1!AV8 -> 0 | BZ8: =订货1!AW8 -> 0 | CC8: =订货1!AX8 -> 0 | CF8: =订货1!AY8 -> 0 | CI8: =订货1!AZ8 -> 0 | CL8: =订货1!BA8 -> 0 | CO8: =订货1!BB8 -> 0 | CR8: =订货1!BC8 -> 0 | CU8: =订货1!BD8 -> 0 | CX8: =订货1!BE8 -> 0 | DA8: =订货1!BF8 -> 0 | DD8: 0 | DE8: =INT(G8/DI8) -> #DIV/0! | DF8: =IFERROR(DD8+H8-G8,"") -> 0 | DG8: =订货1!$Q8 -> 箱 | DH8: =DF8/($DH$2/10000) -> #DIV/0!
A9: =订货1!A9 -> 101686 | B9: =VLOOKUP($A9,订货1!$A9:$G250,7,0) -> 融滋合味（上海）科技有限公司 | C9: =VLOOKUP($A9,订货1!$A9:$H250,8,0) -> 宿州皇冠食品有限公司 | D9: =VLOOKUP($A9,订货1!$A9:$B250,2,0) -> 黄桃丁罐头（825g） | E9: =VLOOKUP($A9,订货1!$A9:$E250,5,0) -> 0.825kg*24can | F9: =VLOOKUP($A9,订货1!$A9:$F250,6,0) -> 箱 | H9: =O9+R9+X9+AA9+AD9+AG9+AJ9+AM9+AP9+AS9+AV9+AY9+BB9+BE9+BH9+BK9+BN9+BQ9+BT9+BW9+BZ9+CC9+CF9+CI9+CL9+CO9+CR9+U9+I9+L9 -> 1 | O9: =订货1!AB9 -> 0 | R9: =订货1!AC9 -> 0 | U9: =订货1!AD9 -> 0 | X9: =订货1!AE9 -> 0 | AA9: =订货1!AF9 -> 0 | AD9: =订货1!AG9 -> 0 | AG9: =订货1!AH9 -> 0 | AJ9: =订货1!AI9 -> 1 | AM9: =订货1!AJ9 -> 0 | AP9: =订货1!AK9 -> 0 | AS9: =订货1!AL9 -> 0 | AV9: =订货1!AM9 -> 0 | AY9: =订货1!AN9 -> 0 | BB9: =订货1!AO9 -> 0 | BE9: =订货1!AP9 -> 0 | BH9: =订货1!AQ9 -> 0 | BK9: =订货1!AR9 -> 0 | BN9: =订货1!AS9 -> 0 | BQ9: =订货1!AT9 -> 0 | BT9: =订货1!AU9 -> 0 | BW9: =订货1!AV9 -> 0 | BZ9: =订货1!AW9 -> 0 | CC9: =订货1!AX9 -> 0 | CF9: =订货1!AY9 -> 0 | CI9: =订货1!AZ9 -> 0 | CL9: =订货1!BA9 -> 0 | CO9: =订货1!BB9 -> 0 | CR9: =订货1!BC9 -> 0 | CU9: =订货1!BD9 -> 0 | CX9: =订货1!BE9 -> 0 | DA9: =订货1!BF9 -> 0 | DD9: 0 | DE9: =INT(G9/DI9) -> #DIV/0! | DF9: =IFERROR(DD9+H9-G9,"") -> 1 | DG9: =订货1!$Q9 -> 箱 | DH9: =DF9/($DH$2/10000) -> #DIV/0!
A10: =订货1!A10 -> 101112 | B10: =VLOOKUP($A10,订货1!$A10:$G251,7,0) -> 上海捷仪经贸有限公司 | C10: =VLOOKUP($A10,订货1!$A10:$H251,8,0) -> 亨氏（青岛）食品有限公司 | D10: =VLOOKUP($A10,订货1!$A10:$B251,2,0) -> 亨氏番茄调味酱 | E10: =VLOOKUP($A10,订货1!$A10:$E251,5,0) -> 10g*600pc | F10: =VLOOKUP($A10,订货1!$A10:$F251,6,0) -> 箱 | H10: =O10+R10+X10+AA10+AD10+AG10+AJ10+AM10+AP10+AS10+AV10+AY10+BB10+BE10+BH10+BK10+BN10+BQ10+BT10+BW10+BZ10+CC10+CF10+CI10+CL10+CO10+CR10+U10+I10+L10 -> 2 | O10: =订货1!AB10 -> 0 | R10: =订货1!AC10 -> 1 | U10: =订货1!AD10 -> 0 | X10: =订货1!AE10 -> 0 | AA10: =订货1!AF10 -> 0 | AD10: =订货1!AG10 -> 0 | AG10: =订货1!AH10 -> 0 | AJ10: =订货1!AI10 -> 0 | AM10: =订货1!AJ10 -> 0 | AP10: =订货1!AK10 -> 0 | AS10: =订货1!AL10 -> 0 | AV10: =订货1!AM10 -> 1 | AY10: =订货1!AN10 -> 0 | BB10: =订货1!AO10 -> 0 | BE10: =订货1!AP10 -> 0 | BH10: =订货1!AQ10 -> 0 | BK10: =订货1!AR10 -> 0 | BN10: =订货1!AS10 -> 0 | BQ10: =订货1!AT10 -> 0 | BT10: =订货1!AU10 -> 0 | BW10: =订货1!AV10 -> 0 | BZ10: =订货1!AW10 -> 0 | CC10: =订货1!AX10 -> 0 | CF10: =订货1!AY10 -> 0 | CI10: =订货1!AZ10 -> 0 | CL10: =订货1!BA10 -> 0 | CO10: =订货1!BB10 -> 0 | CR10: =订货1!BC10 -> 0 | CU10: =订货1!BD10 -> 0 | CX10: =订货1!BE10 -> 0 | DA10: =订货1!BF10 -> 0 | DD10: 0 | DE10: =INT(G10/DI10) -> #DIV/0! | DF10: =IFERROR(DD10+H10-G10,"") -> 2 | DG10: =订货1!$Q10 -> 箱 | DH10: =DF10/($DH$2/10000) -> #DIV/0!
A11: =订货1!A11 -> 101687 | B11: =VLOOKUP($A11,订货1!$A11:$G252,7,0) -> 上海潜深实业有限公司 | C11: =VLOOKUP($A11,订货1!$A11:$H252,8,0) -> 雷州市绿河食品实业有限公司 | D11: =VLOOKUP($A11,订货1!$A11:$B252,2,0) -> 椰果罐头（850g） | E11: =VLOOKUP($A11,订货1!$A11:$E252,5,0) -> 0.85kg*12can | F11: =VLOOKUP($A11,订货1!$A11:$F252,6,0) -> 箱 | H11: =O11+R11+X11+AA11+AD11+AG11+AJ11+AM11+AP11+AS11+AV11+AY11+BB11+BE11+BH11+BK11+BN11+BQ11+BT11+BW11+BZ11+CC11+CF11+CI11+CL11+CO11+CR11+U11+I11+L11 -> 2 | O11: =订货1!AB11 -> 0 | R11: =订货1!AC11 -> 0 | U11: =订货1!AD11 -> 0 | X11: =订货1!AE11 -> 0 | AA11: =订货1!AF11 -> 0 | AD11: =订货1!AG11 -> 1 | AG11: =订货1!AH11 -> 0 | AJ11: =订货1!AI11 -> 0 | AM11: =订货1!AJ11 -> 0 | AP11: =订货1!AK11 -> 0 | AS11: =订货1!AL11 -> 0 | AV11: =订货1!AM11 -> 1 | AY11: =订货1!AN11 -> 0 | BB11: =订货1!AO11 -> 0 | BE11: =订货1!AP11 -> 0 | BH11: =订货1!AQ11 -> 0 | BK11: =订货1!AR11 -> 0 | BN11: =订货1!AS11 -> 0 | BQ11: =订货1!AT11 -> 0 | BT11: =订货1!AU11 -> 0 | BW11: =订货1!AV11 -> 0 | BZ11: =订货1!AW11 -> 0 | CC11: =订货1!AX11 -> 0 | CF11: =订货1!AY11 -> 0 | CI11: =订货1!AZ11 -> 0 | CL11: =订货1!BA11 -> 0 | CO11: =订货1!BB11 -> 0 | CR11: =订货1!BC11 -> 0 | CU11: =订货1!BD11 -> 0 | CX11: =订货1!BE11 -> 0 | DA11: =订货1!BF11 -> 0 | DD11: 0 | DE11: =INT(G11/DI11) -> #DIV/0! | DF11: =IFERROR(DD11+H11-G11,"") -> 2 | DG11: =订货1!$Q11 -> 箱 | DH11: =DF11/($DH$2/10000) -> #DIV/0!
A12: =订货1!A12 -> 101738 | B12: =VLOOKUP($A12,订货1!$A12:$G253,7,0) -> 苏州欧福蛋液股份有限公司 | C12: =VLOOKUP($A12,订货1!$A12:$H253,8,0) -> 苏州欧福蛋液股份有限公司 | D12: =VLOOKUP($A12,订货1!$A12:$B253,2,0) -> （组）巴氏杀菌冰全蛋 | E12: =VLOOKUP($A12,订货1!$A12:$E253,5,0) -> 970g*6 | F12: =VLOOKUP($A12,订货1!$A12:$F253,6,0) -> 组 | H12: =O12+R12+X12+AA12+AD12+AG12+AJ12+AM12+AP12+AS12+AV12+AY12+BB12+BE12+BH12+BK12+BN12+BQ12+BT12+BW12+BZ12+CC12+CF12+CI12+CL12+CO12+CR12+U12+I12+L12 -> 2 | O12: =订货1!AB12 -> 0 | R12: =订货1!AC12 -> 0 | U12: =订货1!AD12 -> 0 | X12: =订货1!AE12 -> 0 | AA12: =订货1!AF12 -> 0 | AD12: =订货1!AG12 -> 1 | AG12: =订货1!AH12 -> 0 | AJ12: =订货1!AI12 -> 0 | AM12: =订货1!AJ12 -> 0 | AP12: =订货1!AK12 -> 0 | AS12: =订货1!AL12 -> 0 | AV12: =订货1!AM12 -> 0 | AY12: =订货1!AN12 -> 1 | BB12: =订货1!AO12 -> 0 | BE12: =订货1!AP12 -> 0 | BH12: =订货1!AQ12 -> 0 | BK12: =订货1!AR12 -> 0 | BN12: =订货1!AS12 -> 0 | BQ12: =订货1!AT12 -> 0 | BT12: =订货1!AU12 -> 0 | BW12: =订货1!AV12 -> 0 | BZ12: =订货1!AW12 -> 0 | CC12: =订货1!AX12 -> 0 | CF12: =订货1!AY12 -> 0 | CI12: =订货1!AZ12 -> 0 | CL12: =订货1!BA12 -> 0 | CO12: =订货1!BB12 -> 0 | CR12: =订货1!BC12 -> 0 | CU12: =订货1!BD12 -> 0 | CX12: =订货1!BE12 -> 0 | DA12: =订货1!BF12 -> 0 | DD12: 0 | DE12: =INT(G12/DI12) -> #DIV/0! | DF12: =IFERROR(DD12+H12-G12,"") -> 2 | DG12: =订货1!$Q12 -> 组 | DH12: =DF12/($DH$2/10000) -> #DIV/0!
A13: =订货1!A13 -> 101688 | B13: =VLOOKUP($A13,订货1!$A13:$G254,7,0) -> 上海宝立食品科技股份有限公司 | C13: =VLOOKUP($A13,订货1!$A13:$H254,8,0) -> 浙江宝立食品科技有限公司 | D13: =VLOOKUP($A13,订货1!$A13:$B254,2,0) -> 奶油蘑菇汤 | E13: =VLOOKUP($A13,订货1!$A13:$E254,5,0) -> 0.16kg*50pc | F13: =VLOOKUP($A13,订货1!$A13:$F254,6,0) -> 箱 | H13: =O13+R13+X13+AA13+AD13+AG13+AJ13+AM13+AP13+AS13+AV13+AY13+BB13+BE13+BH13+BK13+BN13+BQ13+BT13+BW13+BZ13+CC13+CF13+CI13+CL13+CO13+CR13+U13+I13+L13 -> 12 | O13: =订货1!AB13 -> 1 | R13: =订货1!AC13 -> 0 | U13: =订货1!AD13 -> 0 | X13: =订货1!AE13 -> 2 | AA13: =订货1!AF13 -> 1 | AD13: =订货1!AG13 -> 2 | AG13: =订货1!AH13 -> 0 | AJ13: =订货1!AI13 -> 1 | AM13: =订货1!AJ13 -> 0 | AP13: =订货1!AK13 -> 0 | AS13: =订货1!AL13 -> 0 | AV13: =订货1!AM13 -> 2 | AY13: =订货1!AN13 -> 2 | BB13: =订货1!AO13 -> 1 | BE13: =订货1!AP13 -> 0 | BH13: =订货1!AQ13 -> 0 | BK13: =订货1!AR13 -> 0 | BN13: =订货1!AS13 -> 0 | BQ13: =订货1!AT13 -> 0 | BT13: =订货1!AU13 -> 0 | BW13: =订货1!AV13 -> 0 | BZ13: =订货1!AW13 -> 0 | CC13: =订货1!AX13 -> 0 | CF13: =订货1!AY13 -> 0 | CI13: =订货1!AZ13 -> 0 | CL13: =订货1!BA13 -> 0 | CO13: =订货1!BB13 -> 0 | CR13: =订货1!BC13 -> 0 | CU13: =订货1!BD13 -> 0 | CX13: =订货1!BE13 -> 0 | DA13: =订货1!BF13 -> 0 | DD13: 0 | DE13: =INT(G13/DI13) -> #DIV/0! | DF13: =IFERROR(DD13+H13-G13,"") -> 12 | DG13: =订货1!$Q13 -> 箱 | DH13: =DF13/($DH$2/10000) -> #DIV/0!
A14: =订货1!A14 -> 101290 | B14: =VLOOKUP($A14,订货1!$A14:$G255,7,0) -> 上海捷仪经贸有限公司 | C14: =VLOOKUP($A14,订货1!$A14:$H255,8,0) -> 泰州顶淳食品有限公司 | D14: =VLOOKUP($A14,订货1!$A14:$B255,2,0) -> 黑胡椒碎 | E14: =VLOOKUP($A14,订货1!$A14:$E255,5,0) -> 1kg | F14: =VLOOKUP($A14,订货1!$A14:$F255,6,0) -> 袋 | H14: =O14+R14+X14+AA14+AD14+AG14+AJ14+AM14+AP14+AS14+AV14+AY14+BB14+BE14+BH14+BK14+BN14+BQ14+BT14+BW14+BZ14+CC14+CF14+CI14+CL14+CO14+CR14+U14+I14+L14 -> 0 | O14: =订货1!AB14 -> 0 | R14: =订货1!AC14 -> 0 | U14: =订货1!AD14 -> 0 | X14: =订货1!AE14 -> 0 | AA14: =订货1!AF14 -> 0 | AD14: =订货1!AG14 -> 0 | AG14: =订货1!AH14 -> 0 | AJ14: =订货1!AI14 -> 0 | AM14: =订货1!AJ14 -> 0 | AP14: =订货1!AK14 -> 0 | AS14: =订货1!AL14 -> 0 | AV14: =订货1!AM14 -> 0 | AY14: =订货1!AN14 -> 0 | BB14: =订货1!AO14 -> 0 | BE14: =订货1!AP14 -> 0 | BH14: =订货1!AQ14 -> 0 | BK14: =订货1!AR14 -> 0 | BN14: =订货1!AS14 -> 0 | BQ14: =订货1!AT14 -> 0 | BT14: =订货1!AU14 -> 0 | BW14: =订货1!AV14 -> 0 | BZ14: =订货1!AW14 -> 0 | CC14: =订货1!AX14 -> 0 | CF14: =订货1!AY14 -> 0 | CI14: =订货1!AZ14 -> 0 | CL14: =订货1!BA14 -> 0 | CO14: =订货1!BB14 -> 0 | CR14: =订货1!BC14 -> 0 | CU14: =订货1!BD14 -> 0 | CX14: =订货1!BE14 -> 0 | DA14: =订货1!BF14 -> 0 | DD14: 0 | DE14: =INT(G14/DI14) -> #DIV/0! | DF14: =IFERROR(DD14+H14-G14,"") -> 0 | DG14: =订货1!$Q14 -> 袋 | DH14: =DF14/($DH$2/10000) -> #DIV/0!
A15: =订货1!A15 -> 101398 | B15: =VLOOKUP($A15,订货1!$A15:$G256,7,0) -> 上海捷仪经贸有限公司 | C15: =VLOOKUP($A15,订货1!$A15:$H256,8,0) -> 福建好日子食品有限公司 | D15: =VLOOKUP($A15,订货1!$A15:$B256,2,0) -> 好日子红茶 | E15: =VLOOKUP($A15,订货1!$A15:$E256,5,0) -> 2g*100pc*30pc大 | F15: =VLOOKUP($A15,订货1!$A15:$F256,6,0) -> 袋 | H15: =O15+R15+X15+AA15+AD15+AG15+AJ15+AM15+AP15+AS15+AV15+AY15+BB15+BE15+BH15+BK15+BN15+BQ15+BT15+BW15+BZ15+CC15+CF15+CI15+CL15+CO15+CR15+U15+I15+L15 -> 0 | O15: =订货1!AB15 -> 0 | R15: =订货1!AC15 -> 0 | U15: =订货1!AD15 -> 0 | X15: =订货1!AE15 -> 0 | AA15: =订货1!AF15 -> 0 | AD15: =订货1!AG15 -> 0 | AG15: =订货1!AH15 -> 0 | AJ15: =订货1!AI15 -> 0 | AM15: =订货1!AJ15 -> 0 | AP15: =订货1!AK15 -> 0 | AS15: =订货1!AL15 -> 0 | AV15: =订货1!AM15 -> 0 | AY15: =订货1!AN15 -> 0 | BB15: =订货1!AO15 -> 0 | BE15: =订货1!AP15 -> 0 | BH15: =订货1!AQ15 -> 0 | BK15: =订货1!AR15 -> 0 | BN15: =订货1!AS15 -> 0 | BQ15: =订货1!AT15 -> 0 | BT15: =订货1!AU15 -> 0 | BW15: =订货1!AV15 -> 0 | BZ15: =订货1!AW15 -> 0 | CC15: =订货1!AX15 -> 0 | CF15: =订货1!AY15 -> 0 | CI15: =订货1!AZ15 -> 0 | CL15: =订货1!BA15 -> 0 | CO15: =订货1!BB15 -> 0 | CR15: =订货1!BC15 -> 0 | CU15: =订货1!BD15 -> 0 | CX15: =订货1!BE15 -> 0 | DA15: =订货1!BF15 -> 0 | DD15: 0 | DE15: =INT(G15/DI15) -> #DIV/0! | DF15: =IFERROR(DD15+H15-G15,"") -> 0 | DG15: =订货1!$Q15 -> 袋 | DH15: =DF15/($DH$2/10000) -> #DIV/0!
A16: =订货1!A16 -> 101399 | B16: =VLOOKUP($A16,订货1!$A16:$G257,7,0) -> 上海捷仪经贸有限公司 | C16: =VLOOKUP($A16,订货1!$A16:$H257,8,0) -> 福建好日子食品有限公司 | D16: =VLOOKUP($A16,订货1!$A16:$B257,2,0) -> 好日子绿茶 | E16: =VLOOKUP($A16,订货1!$A16:$E257,5,0) -> 2g*100pc*30pc大 | F16: =VLOOKUP($A16,订货1!$A16:$F257,6,0) -> 袋 | H16: =O16+R16+X16+AA16+AD16+AG16+AJ16+AM16+AP16+AS16+AV16+AY16+BB16+BE16+BH16+BK16+BN16+BQ16+BT16+BW16+BZ16+CC16+CF16+CI16+CL16+CO16+CR16+U16+I16+L16 -> 0 | O16: =订货1!AB16 -> 0 | R16: =订货1!AC16 -> 0 | U16: =订货1!AD16 -> 0 | X16: =订货1!AE16 -> 0 | AA16: =订货1!AF16 -> 0 | AD16: =订货1!AG16 -> 0 | AG16: =订货1!AH16 -> 0 | AJ16: =订货1!AI16 -> 0 | AM16: =订货1!AJ16 -> 0 | AP16: =订货1!AK16 -> 0 | AS16: =订货1!AL16 -> 0 | AV16: =订货1!AM16 -> 0 | AY16: =订货1!AN16 -> 0 | BB16: =订货1!AO16 -> 0 | BE16: =订货1!AP16 -> 0 | BH16: =订货1!AQ16 -> 0 | BK16: =订货1!AR16 -> 0 | BN16: =订货1!AS16 -> 0 | BQ16: =订货1!AT16 -> 0 | BT16: =订货1!AU16 -> 0 | BW16: =订货1!AV16 -> 0 | BZ16: =订货1!AW16 -> 0 | CC16: =订货1!AX16 -> 0 | CF16: =订货1!AY16 -> 0 | CI16: =订货1!AZ16 -> 0 | CL16: =订货1!BA16 -> 0 | CO16: =订货1!BB16 -> 0 | CR16: =订货1!BC16 -> 0 | CU16: =订货1!BD16 -> 0 | CX16: =订货1!BE16 -> 0 | DA16: =订货1!BF16 -> 0 | DD16: 0 | DE16: =INT(G16/DI16) -> #DIV/0! | DF16: =IFERROR(DD16+H16-G16,"") -> 0 | DG16: =订货1!$Q16 -> 袋 | DH16: =DF16/($DH$2/10000) -> #DIV/0!
A17: =订货1!A17 -> 101400 | B17: =VLOOKUP($A17,订货1!$A17:$G258,7,0) -> 上海捷仪经贸有限公司 | C17: =VLOOKUP($A17,订货1!$A17:$H258,8,0) -> 福建好日子食品有限公司 | D17: =VLOOKUP($A17,订货1!$A17:$B258,2,0) -> 好日子茉莉花茶 | E17: =VLOOKUP($A17,订货1!$A17:$E258,5,0) -> 2g*100pc*30pc大 | F17: =VLOOKUP($A17,订货1!$A17:$F258,6,0) -> 袋 | H17: =O17+R17+X17+AA17+AD17+AG17+AJ17+AM17+AP17+AS17+AV17+AY17+BB17+BE17+BH17+BK17+BN17+BQ17+BT17+BW17+BZ17+CC17+CF17+CI17+CL17+CO17+CR17+U17+I17+L17 -> 1 | O17: =订货1!AB17 -> 0 | R17: =订货1!AC17 -> 0 | U17: =订货1!AD17 -> 0 | X17: =订货1!AE17 -> 0 | AA17: =订货1!AF17 -> 0 | AD17: =订货1!AG17 -> 0 | AG17: =订货1!AH17 -> 0 | AJ17: =订货1!AI17 -> 0 | AM17: =订货1!AJ17 -> 0 | AP17: =订货1!AK17 -> 0 | AS17: =订货1!AL17 -> 0 | AV17: =订货1!AM17 -> 1 | AY17: =订货1!AN17 -> 0 | BB17: =订货1!AO17 -> 0 | BE17: =订货1!AP17 -> 0 | BH17: =订货1!AQ17 -> 0 | BK17: =订货1!AR17 -> 0 | BN17: =订货1!AS17 -> 0 | BQ17: =订货1!AT17 -> 0 | BT17: =订货1!AU17 -> 0 | BW17: =订货1!AV17 -> 0 | BZ17: =订货1!AW17 -> 0 | CC17: =订货1!AX17 -> 0 | CF17: =订货1!AY17 -> 0 | CI17: =订货1!AZ17 -> 0 | CL17: =订货1!BA17 -> 0 | CO17: =订货1!BB17 -> 0 | CR17: =订货1!BC17 -> 0 | CU17: =订货1!BD17 -> 0 | CX17: =订货1!BE17 -> 0 | DA17: =订货1!BF17 -> 0 | DD17: 0 | DE17: =INT(G17/DI17) -> #DIV/0! | DF17: =IFERROR(DD17+H17-G17,"") -> 1 | DG17: =订货1!$Q17 -> 袋 | DH17: =DF17/($DH$2/10000) -> #DIV/0!
A18: =订货1!A18 -> 201276 | B18: =VLOOKUP($A18,订货1!$A18:$G259,7,0) -> 上海捷仪经贸有限公司 | C18: =VLOOKUP($A18,订货1!$A18:$H259,8,0) -> 广州华糖食品有限公司 | D18: =VLOOKUP($A18,订货1!$A18:$B259,2,0) -> 白糖包 | E18: =VLOOKUP($A18,订货1!$A18:$E259,5,0) -> 7g*250pc | F18: =VLOOKUP($A18,订货1!$A18:$F259,6,0) -> 袋 | H18: =O18+R18+X18+AA18+AD18+AG18+AJ18+AM18+AP18+AS18+AV18+AY18+BB18+BE18+BH18+BK18+BN18+BQ18+BT18+BW18+BZ18+CC18+CF18+CI18+CL18+CO18+CR18+U18+I18+L18 -> 1 | O18: =订货1!AB18 -> 0 | R18: =订货1!AC18 -> 0 | U18: =订货1!AD18 -> 0 | X18: =订货1!AE18 -> 0 | AA18: =订货1!AF18 -> 0 | AD18: =订货1!AG18 -> 0 | AG18: =订货1!AH18 -> 0 | AJ18: =订货1!AI18 -> 0 | AM18: =订货1!AJ18 -> 0 | AP18: =订货1!AK18 -> 0 | AS18: =订货1!AL18 -> 0 | AV18: =订货1!AM18 -> 1 | AY18: =订货1!AN18 -> 0 | BB18: =订货1!AO18 -> 0 | BE18: =订货1!AP18 -> 0 | BH18: =订货1!AQ18 -> 0 | BK18: =订货1!AR18 -> 0 | BN18: =订货1!AS18 -> 0 | BQ18: =订货1!AT18 -> 0 | BT18: =订货1!AU18 -> 0 | BW18: =订货1!AV18 -> 0 | BZ18: =订货1!AW18 -> 0 | CC18: =订货1!AX18 -> 0 | CF18: =订货1!AY18 -> 0 | CI18: =订货1!AZ18 -> 0 | CL18: =订货1!BA18 -> 0 | CO18: =订货1!BB18 -> 0 | CR18: =订货1!BC18 -> 0 | CU18: =订货1!BD18 -> 0 | CX18: =订货1!BE18 -> 0 | DA18: =订货1!BF18 -> 0 | DD18: 0 | DE18: =INT(G18/DI18) -> #DIV/0! | DF18: =IFERROR(DD18+H18-G18,"") -> 1 | DG18: =订货1!$Q18 -> 袋 | DH18: =DF18/($DH$2/10000) -> #DIV/0!
A19: =订货1!A19 -> 101650 | B19: =VLOOKUP($A19,订货1!$A19:$G260,7,0) -> 川商（大連）貿易有限公司 | C19: =VLOOKUP($A19,订货1!$A19:$H260,8,0) -> 河北乾亿食品股份有限公司 | D19: =VLOOKUP($A19,订货1!$A19:$B260,2,0) -> 干辣椒段 | E19: =VLOOKUP($A19,订货1!$A19:$E260,5,0) -> 1kg | F19: =VLOOKUP($A19,订货1!$A19:$F260,6,0) -> 箱 | H19: =O19+R19+X19+AA19+AD19+AG19+AJ19+AM19+AP19+AS19+AV19+AY19+BB19+BE19+BH19+BK19+BN19+BQ19+BT19+BW19+BZ19+CC19+CF19+CI19+CL19+CO19+CR19+U19+I19+L19 -> 1 | O19: =订货1!AB19 -> 0 | R19: =订货1!AC19 -> 0 | U19: =订货1!AD19 -> 0 | X19: =订货1!AE19 -> 0 | AA19: =订货1!AF19 -> 0 | AD19: =订货1!AG19 -> 0 | AG19: =订货1!AH19 -> 0 | AJ19: =订货1!AI19 -> 0 | AM19: =订货1!AJ19 -> 0 | AP19: =订货1!AK19 -> 0 | AS19: =订货1!AL19 -> 0 | AV19: =订货1!AM19 -> 1 | AY19: =订货1!AN19 -> 0 | BB19: =订货1!AO19 -> 0 | BE19: =订货1!AP19 -> 0 | BH19: =订货1!AQ19 -> 0 | BK19: =订货1!AR19 -> 0 | BN19: =订货1!AS19 -> 0 | BQ19: =订货1!AT19 -> 0 | BT19: =订货1!AU19 -> 0 | BW19: =订货1!AV19 -> 0 | BZ19: =订货1!AW19 -> 0 | CC19: =订货1!AX19 -> 0 | CF19: =订货1!AY19 -> 0 | CI19: =订货1!AZ19 -> 0 | CL19: =订货1!BA19 -> 0 | CO19: =订货1!BB19 -> 0 | CR19: =订货1!BC19 -> 0 | CU19: =订货1!BD19 -> 0 | CX19: =订货1!BE19 -> 0 | DA19: =订货1!BF19 -> 0 | DD19: 0 | DE19: =INT(G19/DI19) -> #DIV/0! | DF19: =IFERROR(DD19+H19-G19,"") -> 1 | DG19: =订货1!$Q19 -> 箱 | DH19: =DF19/($DH$2/10000) -> #DIV/0!
A20: =订货1!A20 -> 101025 | B20: =VLOOKUP($A20,订货1!$A20:$G261,7,0) -> 嘉兴铃吉食品有限公司 | C20: =VLOOKUP($A20,订货1!$A20:$H261,8,0) -> 嘉兴铃吉食品有限公司 | D20: =VLOOKUP($A20,订货1!$A20:$B261,2,0) -> 大蒜黄油 | E20: =VLOOKUP($A20,订货1!$A20:$E261,5,0) -> 3kg*4pc | F20: =VLOOKUP($A20,订货1!$A20:$F261,6,0) -> 箱 | H20: =O20+R20+X20+AA20+AD20+AG20+AJ20+AM20+AP20+AS20+AV20+AY20+BB20+BE20+BH20+BK20+BN20+BQ20+BT20+BW20+BZ20+CC20+CF20+CI20+CL20+CO20+CR20+U20+I20+L20 -> 0 | O20: =订货1!AB20 -> 0 | R20: =订货1!AC20 -> 0 | U20: =订货1!AD20 -> 0 | X20: =订货1!AE20 -> 0 | AA20: =订货1!AF20 -> 0 | AD20: =订货1!AG20 -> 0 | AG20: =订货1!AH20 -> 0 | AJ20: =订货1!AI20 -> 0 | AM20: =订货1!AJ20 -> 0 | AP20: =订货1!AK20 -> 0 | AS20: =订货1!AL20 -> 0 | AV20: =订货1!AM20 -> 0 | AY20: =订货1!AN20 -> 0 | BB20: =订货1!AO20 -> 0 | BE20: =订货1!AP20 -> 0 | BH20: =订货1!AQ20 -> 0 | BK20: =订货1!AR20 -> 0 | BN20: =订货1!AS20 -> 0 | BQ20: =订货1!AT20 -> 0 | BT20: =订货1!AU20 -> 0 | BW20: =订货1!AV20 -> 0 | BZ20: =订货1!AW20 -> 0 | CC20: =订货1!AX20 -> 0 | CF20: =订货1!AY20 -> 0 | CI20: =订货1!AZ20 -> 0 | CL20: =订货1!BA20 -> 0 | CO20: =订货1!BB20 -> 0 | CR20: =订货1!BC20 -> 0 | CU20: =订货1!BD20 -> 0 | CX20: =订货1!BE20 -> 0 | DA20: =订货1!BF20 -> 0 | DD20: 0 | DE20: =INT(G20/DI20) -> #DIV/0! | DF20: =IFERROR(DD20+H20-G20,"") -> 0 | DG20: =订货1!$Q20 -> 箱 | DH20: =DF20/($DH$2/10000) -> #DIV/0!
... A69: =订货1!A69 -> 101748 | B69: =VLOOKUP($A69,订货1!$A69:$G310,7,0) -> 辣西西里（北京）国际贸易有限公司 | C69: =VLOOKUP($A69,订货1!$A69:$H310,8,0) -> Dolceria Alba SPA | D69: =VLOOKUP($A69,订货1!$A69:$B310,2,0) -> 酥皮蛋糕 | E69: =VLOOKUP($A69,订货1!$A69:$E310,5,0) -> 60g*4*4 | F69: =VLOOKUP($A69,订货1!$A69:$F310,6,0) -> 盒 | H69: =O69+R69+X69+AA69+AD69+AG69+AJ69+AM69+AP69+AS69+AV69+AY69+BB69+BE69+BH69+BK69+BN69+BQ69+BT69+BW69+BZ69+CC69+CF69+CI69+CL69+CO69+CR69+U69+I69+L69 -> 0 | O69: =订货1!AB69 -> 0 | R69: =订货1!AC69 -> 0 | U69: =订货1!AD69 -> 0 | X69: =订货1!AE69 -> 0 | AA69: =订货1!AF69 -> 0 | AD69: =订货1!AG69 -> 0 | AG69: =订货1!AH69 -> 0 | AJ69: =订货1!AI69 -> 0 | AM69: =订货1!AJ69 -> 0 | AP69: =订货1!AK69 -> 0 | AS69: =订货1!AL69 -> 0 | AV69: =订货1!AM69 -> 0 | AY69: =订货1!AN69 -> 0 | BB69: =订货1!AO69 -> 0 | BE69: =订货1!AP69 -> 0 | BH69: =订货1!AQ69 -> 0 | BK69: =订货1!AR69 -> 0 | BN69: =订货1!AS69 -> 0 | BQ69: =订货1!AT69 -> 0 | BT69: =订货1!AU69 -> 0 | BW69: =订货1!AV69 -> 0 | BZ69: =订货1!AW69 -> 0 | CC69: =订货1!AX69 -> 0 | CF69: =订货1!AY69 -> 0 | CI69: =订货1!AZ69 -> 0 | CL69: =订货1!BA69 -> 0 | CO69: =订货1!BB69 -> 0 | CR69: =订货1!BC69 -> 0 | CU69: =订货1!BD69 -> 0 | CX69: =订货1!BE69 -> 0 | DA69: =订货1!BF69 -> 0 | DD69: 0 | DE69: =INT(G69/DI69) -> #DIV/0! | DF69: =IFERROR(DD69+H69-G69,"") -> 0 | DG69: =订货1!$Q69 -> 盒 | DH69: =DF69/($DH$2/10000) -> #DIV/0!
A70: =订货1!A70 -> 101554 | B70: =VLOOKUP($A70,订货1!$A70:$G312,7,0) -> 辣西西里（北京）国际贸易有限公司 | C70: =VLOOKUP($A70,订货1!$A70:$H312,8,0) -> Dolceria Alba SPA | D70: =VLOOKUP($A70,订货1!$A70:$B312,2,0) -> 焦糖布丁蛋糕 | E70: =VLOOKUP($A70,订货1!$A70:$E312,5,0) -> 100g*9块/盒 | F70: =VLOOKUP($A70,订货1!$A70:$F312,6,0) -> 盒 | H70: =O70+R70+X70+AA70+AD70+AG70+AJ70+AM70+AP70+AS70+AV70+AY70+BB70+BE70+BH70+BK70+BN70+BQ70+BT70+BW70+BZ70+CC70+CF70+CI70+CL70+CO70+CR70+U70+I70+L70 -> 15 | O70: =订货1!AB70 -> 1 | R70: =订货1!AC70 -> 0 | U70: =订货1!AD70 -> 0 | X70: =订货1!AE70 -> 1 | AA70: =订货1!AF70 -> 2 | AD70: =订货1!AG70 -> 3 | AG70: =订货1!AH70 -> 0 | AJ70: =订货1!AI70 -> 0 | AM70: =订货1!AJ70 -> 2 | AP70: =订货1!AK70 -> 0 | AS70: =订货1!AL70 -> 1 | AV70: =订货1!AM70 -> 2 | AY70: =订货1!AN70 -> 3 | BB70: =订货1!AO70 -> 0 | BE70: =订货1!AP70 -> 0 | BH70: =订货1!AQ70 -> 0 | BK70: =订货1!AR70 -> 0 | BN70: =订货1!AS70 -> 0 | BQ70: =订货1!AT70 -> 0 | BT70: =订货1!AU70 -> 0 | BW70: =订货1!AV70 -> 0 | BZ70: =订货1!AW70 -> 0 | CC70: =订货1!AX70 -> 0 | CF70: =订货1!AY70 -> 0 | CI70: =订货1!AZ70 -> 0 | CL70: =订货1!BA70 -> 0 | CO70: =订货1!BB70 -> 0 | CR70: =订货1!BC70 -> 0 | CU70: =订货1!BD70 -> 0 | CX70: =订货1!BE70 -> 0 | DA70: =订货1!BF70 -> 0 | DD70: 0 | DE70: =INT(G70/DI70) -> #DIV/0! | DF70: =IFERROR(DD70+H70-G70,"") -> 15 | DG70: =订货1!$Q70 -> 盒 | DH70: =DF70/($DH$2/10000) -> #DIV/0!
A71: =订货1!A71 -> 101587 | B71: =VLOOKUP($A71,订货1!$A71:$G313,7,0) -> 承武贸易（上海）有限公司 | C71: =VLOOKUP($A71,订货1!$A71:$H313,8,0) -> 山东泰乐源农业科技有限公司 | D71: =VLOOKUP($A71,订货1!$A71:$B313,2,0) -> 金牌印度阿方索芒果（糖浆） | E71: =VLOOKUP($A71,订货1!$A71:$E313,5,0) -> 5kg*4pc | F71: =VLOOKUP($A71,订货1!$A71:$F313,6,0) -> 盒 | H71: =O71+R71+X71+AA71+AD71+AG71+AJ71+AM71+AP71+AS71+AV71+AY71+BB71+BE71+BH71+BK71+BN71+BQ71+BT71+BW71+BZ71+CC71+CF71+CI71+CL71+CO71+CR71+U71+I71+L71 -> 1 | O71: =订货1!AB71 -> 0 | R71: =订货1!AC71 -> 0 | U71: =订货1!AD71 -> 0 | X71: =订货1!AE71 -> 0 | AA71: =订货1!AF71 -> 0 | AD71: =订货1!AG71 -> 0 | AG71: =订货1!AH71 -> 0 | AJ71: =订货1!AI71 -> 1 | AM71: =订货1!AJ71 -> 0 | AP71: =订货1!AK71 -> 0 | AS71: =订货1!AL71 -> 0 | AV71: =订货1!AM71 -> 0 | AY71: =订货1!AN71 -> 0 | BB71: =订货1!AO71 -> 0 | BE71: =订货1!AP71 -> 0 | BH71: =订货1!AQ71 -> 0 | BK71: =订货1!AR71 -> 0 | BN71: =订货1!AS71 -> 0 | BQ71: =订货1!AT71 -> 0 | BT71: =订货1!AU71 -> 0 | BW71: =订货1!AV71 -> 0 | BZ71: =订货1!AW71 -> 0 | CC71: =订货1!AX71 -> 0 | CF71: =订货1!AY71 -> 0 | CI71: =订货1!AZ71 -> 0 | CL71: =订货1!BA71 -> 0 | CO71: =订货1!BB71 -> 0 | CR71: =订货1!BC71 -> 0 | CU71: =订货1!BD71 -> 0 | CX71: =订货1!BE71 -> 0 | DA71: =订货1!BF71 -> 0 | DD71: 0 | DE71: =INT(G71/DI71) -> #DIV/0! | DF71: =IFERROR(DD71+H71-G71,"") -> 1 | DG71: =订货1!$Q71 -> 盒 | DH71: =DF71/($DH$2/10000) -> #DIV/0!
