Workbook
Name 产品名称: OFFSET([1]产品信息!$A$2,,,SUMPRODUCT(N(LEN([1]产品信息!$A:$A)>0)),)
Name 大类: [1]Sheet1!$A$1:$L$1
Name 供货单位名称: [1]供货者!$A$2:$A$99

Sheet Sheet1
E1: ↓此列输入 进货数量 | F1: ↓复制此列数据 （公式勿动，仅复制）
A2: 产品名称 | B2: 产品代码 | C2: 规格 | D2: 进货单位千克数 | E2: 采购数量 | F2: 换算千克数 | G2: 数量单位
A3: 冻鱿鱼圈 | B3: =VLOOKUP(A3,Sheet3!$A:$B,2,0) -> 101015 | C3: =VLOOKUP(A3,Sheet3!$A:$C,3,0) -> 1kg*10pc | D3: 10 | F3: =D3*E3 -> 0 | G3: 千克
A4: 萨莉亚鸡排 | B4: =VLOOKUP(A4,Sheet3!$A:$B,2,0) -> 101022 | C4: =VLOOKUP(A4,Sheet3!$A:$C,3,0) -> 0.15kg*8枚*10pc | D4: 12 | F4: =D4*E4 -> 0 | G4: 千克
A5: 萨莉亚翅中 | B5: =VLOOKUP(A5,Sheet3!$A:$B,2,0) -> 101024 | C5: =VLOOKUP(A5,Sheet3!$A:$C,3,0) -> 1kg*12pc | D5: 12 | F5: =D5*E5 -> 0 | G5: 千克
A6: 大蒜黄油 | B6: =VLOOKUP(A6,Sheet3!$A:$B,2,0) -> 101025 | C6: =VLOOKUP(A6,Sheet3!$A:$C,3,0) -> 3kg*4pc | D6: 12 | F6: =D6*E6 -> 0 | G6: 千克
A7: 海鲜味调味汁 | B7: =VLOOKUP(A7,Sheet3!$A:$B,2,0) -> 101030 | C7: =VLOOKUP(A7,Sheet3!$A:$C,3,0) -> 2kg*5pc | D7: 10 | F7: =D7*E7 -> 0 | G7: 千克
A8: 冻煮杂色蛤 | B8: =VLOOKUP(A8,Sheet3!$A:$B,2,0) -> 101040 | C8: =VLOOKUP(A8,Sheet3!$A:$C,3,0) -> 0.096kg*50pc | D8: 4.8 | E8: 1 | F8: =D8*E8 -> 4.8 | G8: 千克
A9: 蔬菜汤 | B9: =VLOOKUP(A9,Sheet3!$A:$B,2,0) -> 101055 | C9: =VLOOKUP(A9,Sheet3!$A:$C,3,0) -> 1kg*10pc | D9: 10 | F9: =D9*E9 -> 0 | G9: 千克
A10: 妙可蓝多马苏里拉奶酪 | B10: =VLOOKUP(A10,Sheet3!$A:$B,2,0) -> 101063 | C10: =VLOOKUP(A10,Sheet3!$A:$C,3,0) -> 3kg*4pc | D10: 12 | E10: 1 | F10: =D10*E10 -> 12 | G10: 千克
A11: 萨莉亚速冻蜗牛肉 | B11: =VLOOKUP(A11,Sheet3!$A:$B,2,0) -> 101073 | C11: =VLOOKUP(A11,Sheet3!$A:$C,3,0) -> 1kg*12pc | D11: 12 | E11: 1 | F11: =D11*E11 -> 12 | G11: 千克
A12: 法排小切 | B12: =VLOOKUP(A12,Sheet3!$A:$B,2,0) -> 101189 | C12: =VLOOKUP(A12,Sheet3!$A:$C,3,0) -> 0.9kg*14pc | D12: 12.6 | F12: =D12*E12 -> 0 | G12: 千克
A13: 香草鸡排串 | B13: =VLOOKUP(A13,Sheet3!$A:$B,2,0) -> 101269 | C13: =VLOOKUP(A13,Sheet3!$A:$C,3,0) -> 1kg*12 | D13: 12 | F13: =D13*E13 -> 0 | G13: 千克
A14: 伊利冰淇淋（香草口味） | B14: =VLOOKUP(A14,Sheet3!$A:$B,2,0) -> 101329 | C14: =VLOOKUP(A14,Sheet3!$A:$C,3,0) -> 3.5kg | D14: 3.5 | F14: =D14*E14 -> 0 | G14: 千克
A15: 早餐培根1 | B15: =VLOOKUP(A15,Sheet3!$A:$B,2,0) -> 101332 | C15: =VLOOKUP(A15,Sheet3!$A:$C,3,0) -> 1kg*12pc | D15: 12 | F15: =D15*E15 -> 0 | G15: 千克
A16: 超大熔岩蛋糕 | B16: =VLOOKUP(A16,Sheet3!$A:$B,2,0) -> 101490 | C16: =VLOOKUP(A16,Sheet3!$A:$C,3,0) -> 0.09kg*18pc | D16: 1.62 | E16: 1 | F16: =D16*E16 -> 1.62 | G16: 千克
A17: 肉酱 | B17: =VLOOKUP(A17,Sheet3!$A:$B,2,0) -> 101508 | C17: =VLOOKUP(A17,Sheet3!$A:$C,3,0) -> 1kg*10pkt | D17: 10 | F17: 0 | G17: 千克
A18: 9寸实验饼底 | B18: =VLOOKUP(A18,Sheet3!$A:$B,2,0) -> 101543 | C18: =VLOOKUP(A18,Sheet3!$A:$C,3,0) -> 0.16kg*60pc | D18: 9.6 | F18: =D18*E18 -> 0 | G18: 千克
A19: 焦糖布丁蛋糕 | B19: =VLOOKUP(A19,Sheet3!$A:$B,2,0) -> 101554 | C19: =VLOOKUP(A19,Sheet3!$A:$C,3,0) -> 0.1kg*9pc | D19: 0.9 | E19: 4 | F19: =D19*E19 -> 3.6 | G19: 千克
A20: 白沙司 | B20: =VLOOKUP(A20,Sheet3!$A:$B,2,0) -> 101576 | C20: =VLOOKUP(A20,Sheet3!$A:$C,3,0) -> 1kg*12 | D20: 12 | F20: =D20*E20 -> 0 | G20: 千克
A21: 意式肉酱 | B21: =VLOOKUP(A21,Sheet3!$A:$B,2,0) -> 101581 | C21: =VLOOKUP(A21,Sheet3!$A:$C,3,0) -> 1kg*10pkt | D21: 10 | E21: 1 | F21: =D21*E21 -> 10 | G21: 千克
A22: 麻辣肉酱 | B22: =VLOOKUP(A22,Sheet3!$A:$B,2,0) -> 101594 | C22: =VLOOKUP(A22,Sheet3!$A:$C,3,0) -> 1kg*10pc | D22: 10 | F22: =D22*E22 -> 0 | G22: 千克
A23: 罗勒松子酱 | B23: =VLOOKUP(A23,Sheet3!$A:$B,2,0) -> 101595 | C23: =VLOOKUP(A23,Sheet3!$A:$C,3,0) -> 1kg*10pc | D23: 10 | F23: =D23*E23 -> 0 | G23: 千克
A24: 黑胡椒酱 | B24: =VLOOKUP(A24,Sheet3!$A:$B,2,0) -> 101597 | C24: =VLOOKUP(A24,Sheet3!$A:$C,3,0) -> 1kg*10pc | D24: 10 | E24: 1 | F24: =D24*E24 -> 10 | G24: 千克
A25: 冷冻三文鱼块 | B25: =VLOOKUP(A25,Sheet3!$A:$B,2,0) -> 101606 | C25: =VLOOKUP(A25,Sheet3!$A:$C,3,0) -> 0.12kg*50pc | D25: 6 | F25: =D25*E25 -> 0 | G25: 千克
A26: 西冷牛排切片SA | B26: =VLOOKUP(A26,Sheet3!$A:$B,2,0) -> 101608 | C26: =VLOOKUP(A26,Sheet3!$A:$C,3,0) -> 0.15kg*100pc | D26: 15 | E26: 1 | F26: =D26*E26 -> 15 | G26: 千克
A27: 熟虾尾 | B27: =VLOOKUP(A27,Sheet3!$A:$B,2,0) -> 101610 | C27: =VLOOKUP(A27,Sheet3!$A:$C,3,0) -> 1kg*10pkt | D27: 10 | F27: =D27*E27 -> 0 | G27: 千克
A28: 冻鱿鱼 | B28: =VLOOKUP(A28,Sheet3!$A:$B,2,0) -> 101617 | C28: =VLOOKUP(A28,Sheet3!$A:$C,3,0) -> 9.8kg | D28: 9.8 | F28: =D28*E28 -> 0 | G28: 千克
A29: 芝士粉 | B29: =VLOOKUP(A29,Sheet3!$A:$B,2,0) -> 101624 | C29: =VLOOKUP(A29,Sheet3!$A:$C,3,0) -> 1kg*10pkt | D29: 10 | F29: =D29*E29 -> 0 | G29: 千克
A30: 萨莉亚冷冻小法棍600g | B30: =VLOOKUP(A30,Sheet3!$A:$B,2,0) -> 101635 | C30: =VLOOKUP(A30,Sheet3!$A:$C,3,0) -> 0.6kg*6pkt | D30: 3.6 | E30: 1 | F30: =D30*E30 -> 3.6 | G30: 千克
A31: 新香烤翅中 | B31: =VLOOKUP(A31,Sheet3!$A:$B,2,0) -> 101638 | C31: =VLOOKUP(A31,Sheet3!$A:$C,3,0) -> 1kg*12pc | D31: 12 | F31: =D31*E31 -> 0 | G31: 千克
A32: 原味鸡腿排 | B32: =VLOOKUP(A32,Sheet3!$A:$B,2,0) -> 101640 | C32: =VLOOKUP(A32,Sheet3!$A:$C,3,0) -> 0.15kg*8枚*10pc | D32: 12 | F32: =D32*E32 -> 0 | G32: 千克
A33: 萨莉亚鸡排串 | B33: =VLOOKUP(A33,Sheet3!$A:$B,2,0) -> 101641 | C33: =VLOOKUP(A33,Sheet3!$A:$C,3,0) -> 1kg*12 | D33: 12 | F33: =D33*E33 -> 0 | G33: 千克
A34: 萨莉亚专用白沙司 | B34: =VLOOKUP(A34,Sheet3!$A:$B,2,0) -> 101652 | C34: =VLOOKUP(A34,Sheet3!$A:$C,3,0) -> 1kg*12pc | D34: 12 | F34: =D34*E34 -> 0 | G34: 千克
A35: 面包虾 | B35: =VLOOKUP(A35,Sheet3!$A:$B,2,0) -> 101655 | C35: =VLOOKUP(A35,Sheet3!$A:$C,3,0) -> 0.5kg*16pc | D35: 8 | F35: =D35*E35 -> 0 | G35: 千克
A36: 法式羊排 | B36: =VLOOKUP(A36,Sheet3!$A:$B,2,0) -> 101664 | C36: =VLOOKUP(A36,Sheet3!$A:$C,3,0) -> 1.08kg*12pkt | D36: 12.96 | F36: =D36*E36 -> 0 | G36: 千克
A37: 速冻菠菜段 | B37: =VLOOKUP(A37,Sheet3!$A:$B,2,0) -> 101671 | C37: =VLOOKUP(A37,Sheet3!$A:$C,3,0) -> 2kg*6pc | D37: 12 | E37: 1 | F37: =D37*E37 -> 12 | G37: 千克
A38: 速冻甜玉米粒 | B38: =VLOOKUP(A38,Sheet3!$A:$B,2,0) -> 101672 | C38: =VLOOKUP(A38,Sheet3!$A:$C,3,0) -> 3kg*4pc | D38: 12 | F38: =D38*E38 -> 0 | G38: 千克
A39: 焦糖布丁 | B39: =VLOOKUP(A39,Sheet3!$A:$B,2,0) -> 101677 | C39: =VLOOKUP(A39,Sheet3!$A:$C,3,0) -> 0.1kg*6pc | D39: 0.6 | F39: =D39*E39 -> 0 | G39: 千克
A40: 菌菇调理包 | B40: =VLOOKUP(A40,Sheet3!$A:$B,2,0) -> 101678 | C40: =VLOOKUP(A40,Sheet3!$A:$C,3,0) -> 1kg*10pc | D40: 10 | F40: =D40*E40 -> 0 | G40: 千克
...

Sheet Sheet2
B1: 冻鱿鱼圈 | C1: 101015 | E1: 冻鱿鱼圈 | F1: 101015
B2: 萨莉亚鸡排 | C2: 101022 | E2: 萨莉亚鸡排 | F2: 101022
B3: 萨莉亚翅中 | C3: 101024 | E3: 萨莉亚翅中 | F3: 101024
B4: 大蒜黄油 | C4: 101025 | E4: 大蒜黄油 | F4: 101025
B5: 海鲜味调味汁 | C5: 101030 | E5: 海鲜味调味汁 | F5: 101030
B6: 冻煮杂色蛤 | C6: 101040 | E6: 冻煮杂色蛤 | F6: 101040
B7: 蔬菜汤 | C7: 101055 | E7: 蔬菜汤 | F7: 101055
B8: 妙可蓝多马苏里拉奶酪 | C8: 101063 | E8: 妙可蓝多马苏里拉奶酪 | F8: 101063
B9: 萨莉亚速冻蜗牛肉 | C9: 101073 | E9: 萨莉亚速冻蜗牛肉 | F9: 101073
B10: 法排小切 | C10: 101189 | E10: 法排小切 | F10: 101189
B11: 香草鸡排串 | C11: 101269 | E11: 香草鸡排串 | F11: 101269
B12: 伊利冰淇淋（香草口味） | C12: 101329 | E12: 伊利冰淇淋（香草口味） | F12: 101329
... B101: 贝贝罗尼意式萨拉米 | C101: 101714 | E101: 贝贝罗尼意式萨拉米 | F101: 101714
B102: 稀奶油 | C102: 101746 | E102: 稀奶油 | F102: 101746
B103: 百蒂凯-樱桃番茄 | C103: 720003 | E103: 百蒂凯-樱桃番茄 | F103: 720003
B104: 百蒂凯-彩椒丝 | C104: 720004 | E104: 百蒂凯-彩椒丝 | F104: 720004
B105: 百蒂凯-蔬菜底料 | C105: 720005 | E105: 百蒂凯-蔬菜底料 | F105: 720005
B106: 百蒂凯-火龙果 | C106: 720013 | E106: 百蒂凯-火龙果 | F106: 720013
B107: 百蒂凯-混合色拉 | C107: 720017 | E107: 百蒂凯-混合色拉 | F107: 720017
B108: 赛沛弗-混合色拉 | C108: 730017 | E108: 赛沛弗-混合色拉 | F108: 730017
B109: 赛沛弗-樱桃番茄 | C109: 730003 | E109: 赛沛弗-樱桃番茄 | F109: 730003
B110: 赛沛弗-彩椒丝 | C110: 730004 | E110: 赛沛弗-彩椒丝 | F110: 730004
B111: 赛沛弗-蔬菜底料 | C111: 730005 | E111: 赛沛弗-蔬菜底料 | F111: 730005
B112: 赛沛弗-火龙果 | C112: 730013 | E112: 赛沛弗-火龙果 | F112: 730013
B113: 赛沛弗-芝麻菜 | C113: 730011 | E113: 赛沛弗-芝麻菜 | F113: 730011
B114: 百蒂凯-芝麻菜 | C114: 720011 | E114: 百蒂凯-芝麻菜 | F114: 720011
... B159: 可可粉 | C159: 101729 | E159: 可可粉 | F159: 101729
B160: 利梭多粉 | C160: 101730 | E160: 利梭多粉 | F160: 101730
B161: 海苔片2*35毫米 | C161: 101757 | E161: 海苔片2*35毫米 | F161: 101730
B162: 酸汤鱼金汤料 | C162: 101763 | E162: 酸汤鱼金汤料 | F162: 101730
B163: 扁可颂面包 | C163: 101769 | E163: 扁可颂面包 | F163: 101730
B164: 白糖包 | C164: 201276 | E164: 白糖包 | F164: 201276
B165: 万家宴一级大豆油 | C165: 301115 | E165: 万家宴一级大豆油 | F165: 301115
B166: 萨莉亚沙拉酱 | C166: 401286 | E166: 萨莉亚沙拉酱 | F166: 401286
B167: 可口可乐糖浆 | C167: 700001 | E167: 可口可乐糖浆 | F167: 700001
B168: 雪碧糖浆 | C168: 700002 | E168: 雪碧糖浆 | F168: 700002
B169: 芬达橙汁糖浆 | C169: 700003 | E169: 芬达橙汁糖浆 | F169: 700003
B170: 飞想柠檬红茶 | C170: 700004 | E170: 飞想柠檬红茶 | F170: 700004
B171: 零度可乐糖浆 | C171: 700006 | E171: 零度可乐糖浆 | F171: 700006
B172: 可口可乐糖浆 | C172: 700001 | E172: 可口可乐糖浆 | F172: 700001
...

Sheet Sheet3
A1: 可口可乐糖浆 | B1: 700001 | C1: 10L
A2: 雪碧糖浆 | B2: 700002 | C2: 10L
A3: 芬达橙汁糖浆 | B3: 700003 | C3: 10L
A4: 飞想柠檬红茶 | B4: 700004 | C4: 10L
A5: 零度可乐糖浆 | B5: 700006 | C5: 10L
A6: 赛沛弗-混合色拉 | B6: 730017 | C6: 0.6kg
A7: 赛沛弗-樱桃番茄 | B7: 730003 | C7: 0.5kg
A8: 赛沛弗-蔬菜底料 | B8: 730005 | C8: 1kg
A9: 赛沛弗-火龙果 | B9: 730013 | C9: 0.6kg
A10: 百蒂凯-樱桃番茄 | B10: 720003 | C10: 0.5kg
A11: 百蒂凯-蔬菜底料 | B11: 720005 | C11: 1kg
A12: 百蒂凯-混合色拉 | B12: 720017 | C12: 0.6kg
... A195: 屯河番茄丁 | B195: 101782 | C195: 2.85kg*6can
